Workbook

Sheet Python vs Excel
A1: Matching outputs: Python (statsmodels) vs Excel (formulas in this workbook)
A2: Python values are pasted from results.json. Excel values are live formulas. Difference should be ~0.
A4: Statistic | B4: Python | C4: Excel | D4: Difference | E4: Match | F4: Excel location
A5: ADF, ln F level | B5: -2.309 | C5: ='1 ADF'!B16 -> -2.309109 | D5: =C5-B5 -> -0.00010902925 | E5: =IF(ABS(D5)<=0.0015,"Yes","No") -> Yes | F5: 1 ADF!B16
A6: ADF, ln B level | B6: -2.367 | C6: ='1 ADF'!B26 -> -2.3671437 | D6: =C6-B6 -> -0.00014366899 | E6: =IF(ABS(D6)<=0.0015,"Yes","No") -> Yes | F6: 1 ADF!B26
A7: Hedge ratio β | B7: 0.91613 | C7: ='2 Hedge ratio'!B5 -> 0.91612676 | D7: =C7-B7 -> -3.2407533e-06 | E7: =IF(ABS(D7)<=0.0015,"Yes","No") -> Yes | F7: 2 Hedge ratio!B5
A8: R² (Step 2) | B8: 0.99564 | C8: ='2 Hedge ratio'!B8 -> 0.99563563 | D8: =C8-B8 -> -4.3730976e-06 | E8: =IF(ABS(D8)<=0.0015,"Yes","No") -> Yes | F8: 2 Hedge ratio!B8
A9: Mean ratio F/B | B9: 89.6795 | C9: ='2 Hedge ratio'!B9 -> 89.679532 | D9: =C9-B9 -> 3.2223533e-05 | E9: =IF(ABS(D9)<=0.0015,"Yes","No") -> Yes | F9: 2 Hedge ratio!B9
A10: Engle–Granger, constant only | B10: -3.096 | C10: ='3 Cointegration'!B7 -> -3.096125 | D10: =C10-B10 -> -0.00012495995 | E10: =IF(ABS(D10)<=0.0015,"Yes","No") -> Yes | F10: 3 Cointegration!B7
A11: Trend in ln(F/B), % per year | B11: -0.01161 | C11: =Carry!B5 -> -0.011614056 | D11: =C11-B11 -> -4.0560557e-06 | E11: =IF(ABS(D11)<=0.00015,"Yes","No") -> Yes | F11: Carry!B5
A12: Implied financing rate r | B12: 0.0654 | C12: =Carry!B9 -> 0.065383462 | D12: =C12-B12 -> -1.6538206e-05 | E12: =IF(ABS(D12)<=0.00015,"Yes","No") -> Yes | F12: Carry!B9
A13: β with trend | B13: 0.99697 | C13: ='5 Re-specification'!B5 -> 0.9969695 | D13: =C13-B13 -> -5.0002121e-07 | E13: =IF(ABS(D13)<=0.0015,"Yes","No") -> Yes | F13: 5 Re-specification!B5
A14: δ, % per year | B14: -0.0113 | C14: ='5 Re-specification'!B8 -> -0.011322188 | D14: =C14-B14 -> -2.218816e-05 | E14: =IF(ABS(D14)<=0.00015,"Yes","No") -> Yes | F14: 5 Re-specification!B8
A15: Engle–Granger, constant + trend | B15: -8.06 | C15: ='5b EG with trend'!B7 -> -8.0604248 | D15: =C15-B15 -> -0.00042484857 | E15: =IF(ABS(D15)<=0.0015,"Yes","No") -> Yes | F15: 5b EG with trend!B7
A16: ECM γ | B16: -0.4832 | C16: ='6 ECM'!B5 -> -0.48320184 | D16: =C16-B16 -> -1.8390417e-06 | E16: =IF(ABS(D16)<=0.0015,"Yes","No") -> Yes | F16: 6 ECM!B5
A17: Half-life (sessions) | B17: 1.43 | C17: ='6 ECM'!B8 -> 1.4344879 | D17: =C17-B17 -> 0.0044878776 | E17: =IF(ABS(D17)<=0.01,"Yes","No") -> Yes | F17: 6 ECM!B8
A18: Signal: trades | B18: 29 | C18: ='7 Signal backtest'!B5 -> 29 | D18: =C18-B18 -> 0 | E18: =IF(ABS(D18)<=0.0015,"Yes","No") -> Yes | F18: 7 Signal backtest!B5
A19: Signal: annual excess return | B19: 0.00515 | C19: ='7 Signal backtest'!B6 -> 0.0051470199 | D19: =C19-B19 -> -2.9801451e-06 | E19: =IF(ABS(D19)<=0.00015,"Yes","No") -> Yes | F19: 7 Signal backtest!B6
A20: Signal: Sharpe ratio | B20: 0.39 | C20: ='7 Signal backtest'!B8 -> 0.3874636 | D20: =C20-B20 -> -0.002536399 | E20: =IF(ABS(D20)<=0.01,"Yes","No") -> Yes | F20: 7 Signal backtest!B8
A21: Aarav: return above risk-free | B21: 0.0019 | C21: ='8 Four people'!B11 -> 0.0018938314 | D21: =C21-B21 -> -6.1685821e-06 | E21: =IF(ABS(D21)<=0.00015,"Yes","No") -> Yes | F21: 8 Four people!B11
A22: Meera: return above risk-free | B22: -0.0165 | C22: ='8 Four people'!C11 -> -0.016478315 | D22: =C22-B22 -> 2.1684979e-05 | E22: =IF(ABS(D22)<=0.00015,"Yes","No") -> Yes | F22: 8 Four people!C11
A23: Rohan: return on incremental cash | B23: -0.4599 | C23: ='8 Four people'!D11 -> -0.45987695 | D23: =C23-B23 -> 2.3046087e-05 | E23: =IF(ABS(D23)<=0.00015,"Yes","No") -> Yes | F23: 8 Four people!D11
A24: Kavya: return on incremental capital | B24: 0.206 | C24: ='8 Four people'!E11 -> 0.20596351 | D24: =C24-B24 -> -3.6494166e-05 | E24: =IF(ABS(D24)<=0.00015,"Yes","No") -> Yes | F24: 8 Four people!E11
A25: 15-min signal: annual net, % of notional | B25: 0.0213 | C25: ='9 Trades 15-min'!F102 -> 0.021338868 | D25: =C25-B25 -> 3.8868323e-05 | E25: =IF(ABS(D25)<=0.00015,"Yes","No") -> Yes | F25: 9 Trades 15-min, summary
A26: 15-min Aarav: return above risk-free | B26: 0.0172 | C26: ='9 Trades 15-min'!F103 -> 0.017220043 | D26: =C26-B26 -> 2.0043189e-05 | E26: =IF(ABS(D26)<=0.00015,"Yes","No") -> Yes | F26: 9 Trades 15-min, summary
A27: 15-min Meera: return above risk-free | B27: -0.0096 | C27: ='9 Trades 15-min'!F104 -> -0.0095932673 | D27: =C27-B27 -> 6.7327487e-06 | E27: =IF(ABS(D27)<=0.00015,"Yes","No") -> Yes | F27: 9 Trades 15-min, summary
A28: 15-min Rohan: return on extra cash | B28: 0.5044 | C28: ='9 Trades 15-min'!F105 -> 0.50438368 | D28: =C28-B28 -> -1.6317226e-05 | E28: =IF(ABS(D28)<=0.00015,"Yes","No") -> Yes | F28: 9 Trades 15-min, summary
A29: 15-min Kavya: return on margin | B29: 0.4948 | C29: ='9 Trades 15-min'!F106 -> 0.49481747 | D29: =C29-B29 -> 1.7468838e-05 | E29: =IF(ABS(D29)<=0.00015,"Yes","No") -> Yes | F29: 9 Trades 15-min, summary
A30: Course test: one-sample t on trades | B30: 3.06 | C30: ='10 Course tests'!B7 -> 3.0579229 | D30: =C30-B30 -> -0.0020771309 | E30: =IF(ABS(D30)<=0.01,"Yes","No") -> Yes | F30: 10 Course tests!B7
A31: Course test: Welch p, two halves | B31: 0.663 | C31: ='10 Course tests'!B15 -> 0.66301579 | D31: =C31-B31 -> 1.5794897e-05 | E31: =IF(ABS(D31)<=0.01,"Yes","No") -> Yes | F31: 10 Course tests!B15
A32: Course test: chi-square p | B32: 0.1277 | C32: ='10 Course tests'!B24 -> 0.12767494 | D32: =C32-B32 -> -2.5062103e-05 | E32: =IF(ABS(D32)<=0.01,"Yes","No") -> Yes | F32: 10 Course tests!B24
A34: Tolerance reflects display rounding of the pasted Python values (3–5 decimals).

Sheet Inputs
A1: Inputs and assumptions
A2: Blue = input you may change. Every other sheet recalculates from these.
A4: Parameter | B4: Value | C4: Source / note
A5: Entry threshold |z| > | B5: 2 | C5: Rule, fixed before any results were seen
A6: Exit threshold |z| < | B6: 0.5
A7: Stop-loss |z| > | B7: 3.5
A8: Time stop (sessions) | B8: 10 | C8: ≈ 7 half-lives
A9: Rolling estimation window (sessions) | B9: 250 | C9: Walk-forward: only the previous 250 sessions are used
A10: Minimum observations before trading | B10: 60
A11: NIFTY lot size (units) | B11: 65 | C11: NSE circular FAOP70616: 75 → 65 from the January 2026 series
A12: Futures margin, % of notional | B12: 0.13 | C12: Assumption: SPAN + exposure margin
A13: Retail MTF interest rate | B13: 0.14 | C13: Assumption: within the 12–18% p.a. range charged by Indian brokers
A14: Institutional funding spread over repo | B14: 0.0075 | C14: Assumption
A15: Cross-margin relief (institution) | B15: 0.7 | C15: Assumption; NSE Clearing permits index futures vs ETF cross-margining
A16: Trading days per year | B16: 252 | C16: Annualisation convention
A17: Futures stamp duty (buy side) | B17: 2e-05 | C17: Indian Stamp Act: 0.002% on futures purchases
A18: Futures other charges per side — retail | B18: 3.5e-05 | C18: Exchange txn + SEBI fee + GST + brokerage (approx.)
A19: Futures slippage per side — retail | B19: 0.0001 | C19: Assumption: 1.0 bp
A20: ETF stamp duty (buy side) | B20: 0.00015 | C20: Indian Stamp Act: 0.015% on delivery purchases
A21: ETF STT (sell side) | B21: 1e-05 | C21: 0.001% on sale of equity-oriented fund units
A22: ETF other charges per side — retail | B22: 5e-05 | C22: Exchange txn + SEBI fee + GST + DP (approx.)
... A30: Brokerage per option order — institution | B30: 1e-06 | C30: Assumption
A32: Futures STT (sell side) is time-varying and sits in Panel column O: 0.0125% to 30-Sep-2024, 0.02% to 31-Mar-2026, 0.05% from 1-Apr-2026 (Union Budgets 2024 and 2026).
A33: Risk-free rate = RBI policy repo path (Panel column N): 6.50% → 6.25% (7-Feb-25) → 6.00% (9-Apr-25) → 5.50% (6-Jun-25) → 5.25% (5-Dec-25).

Sheet Panel
A1: Daily panel and walk-forward backtest (811 sessions)
A2: Columns B, C, G, K, L, N, O are data. Everything else is a formula. Row 5 is the first session.
A4: Date | B4: FUT close | C4: BEES close | D4: ln F | E4: ln B | F4: t | G4: DTE | H4: ln(F/B) | I4: Δ ln F | J4: Δ ln B | K4: Expiry | L4: Splice | M4: Δ ln F adj | N4: Repo | O4: STT fut | P4: Resid naive | Q4: Resid trend | R4: Window | S4: δ roll | T4: β roll | U4: α roll | V4: σ roll | W4: z | X4: held pre | Y4: exit | Z4: cur after | AA4: entry | AB4: POS | AC4: held | AD4: β hold | AE4: ΔqF | AF4: qB | AG4: ΔqB | AH4: Cost retail | AI4: x SIGNAL | AJ4: Cost inst | AK4: x KAVYA | AL4: held pre S | AM4: exit S | AN4: cur after S | AO4: entry S | AP4: POS S | AQ4: held S | AR4: β hold S | AS4: ΔqF S | AT4: qB S | AU4: ΔqB S | AV4: Cost S | AW4: x AARAV | AX4: x MEERA | AY4: Cost fut S | AZ4: x ROHAN | BA4: Cum signal | BB4: Run max | BC4: Drawdown | BD4: Cal days
A5: 45048 | B5: 18202 | C5: 198.2 | D5: =LN(B5) -> 9.8092868 | E5: =LN(C5) -> 5.2892766 | F5: 0 | G5: 23 | H5: =D5-E5 -> 4.5200101 | I5: 0 | J5: 0 | K5: 0 | L5: 0 | M5: 0 | N5: 0.065 | O5: 0.000125 | P5: =D5-('2 Hedge ratio'!$B$6+'2 Hedge ratio'!$B$5*E5) -> 0.0018188254 | Q5: =D5-('5 Re-specification'!$B$7+'5 Re-specification'!$B$5*E5+'5 Re-specification'!$B$6*F5) -> 0.0048382672 | R5: =MIN(F5,Inputs!$B$9) -> 0 | S5: =IF(AND(F5>=1,R5>=Inputs!$B$10),INDEX(LINEST(OFFSET(D5,-R5,0,R5,1),OFFSET(E5,-R5,0,R5,2)),1,1),"") | T5: =IF(AND(F5>=1,R5>=Inputs!$B$10),INDEX(LINEST(OFFSET(D5,-R5,0,R5,1),OFFSET(E5,-R5,0,R5,2)),1,2),"") | U5: =IF(AND(F5>=1,R5>=Inputs!$B$10),INDEX(LINEST(OFFSET(D5,-R5,0,R5,1),OFFSET(E5,-R5,0,R5,2)),1,3),"") | V5: =IF(AND(F5>=1,R5>=Inputs!$B$10),SQRT(SUMPRODUCT((OFFSET(D5,-R5,0,R5,1)-U5-T5*OFFSET(E5,-R5,0,R5,1)-S5*OFFSET(F5,-R5,0,R5,1))^2)/(R5-3)),"") | W5: =IF(AND(F5>=1,R5>=Inputs!$B$10),(D5-U5-T5*E5-S5*F5)/V5,"") | X5: 0 | Y5: 0 | Z5: 0 | AA5: 0 | AB5: 0 | AC5: 0 | AD5: 0 | AE5: 0 | AF5: 0 | AG5: 0 | AH5: 0 | AI5: 0 | AJ5: 0 | AK5: 0 | AL5: 0 | AM5: 0 | AN5: 0 | AO5: 0 | AP5: 0 | AQ5: 0 | AR5: 0 | AS5: 0 | AT5: 0 | AU5: 0 | AV5: 0 | AW5: 0 | AX5: 0 | AY5: 0 | AZ5: 0 | BA5: =AI5 -> 0 | BB5: =MAX(0,BA5) -> 0 | BC5: =BA5-BB5 -> 0 | BD5: =A6-A5 -> 1
A6: 45049 | B6: 18147.3 | C6: 197.58 | D6: =LN(B6) -> 9.8062771 | E6: =LN(C6) -> 5.2861436 | F6: 1 | G6: 22 | H6: =D6-E6 -> 4.5201335 | I6: =D6-D5 -> -0.0030096888 | J6: =E6-E5 -> -0.0031330563 | K6: 0 | L6: 0 | M6: =IF(L6=1,J6-Carry!$B$9/Inputs!$B$16,I6) -> -0.0030096888 | N6: 0.065 | O6: 0.000125 | P6: =D6-('2 Hedge ratio'!$B$6+'2 Hedge ratio'!$B$5*E6) -> 0.0016794133 | Q6: =D6-('5 Re-specification'!$B$7+'5 Re-specification'!$B$5*E6+'5 Re-specification'!$B$6*F6) -> 0.0049970692 | R6: =MIN(F6,Inputs!$B$9) -> 1 | S6: =IF(AND(F6>=1,R6>=Inputs!$B$10),INDEX(LINEST(OFFSET(D6,-R6,0,R6,1),OFFSET(E6,-R6,0,R6,2)),1,1),"") | T6: =IF(AND(F6>=1,R6>=Inputs!$B$10),INDEX(LINEST(OFFSET(D6,-R6,0,R6,1),OFFSET(E6,-R6,0,R6,2)),1,2),"") | U6: =IF(AND(F6>=1,R6>=Inputs!$B$10),INDEX(LINEST(OFFSET(D6,-R6,0,R6,1),OFFSET(E6,-R6,0,R6,2)),1,3),"") | V6: =IF(AND(F6>=1,R6>=Inputs!$B$10),SQRT(SUMPRODUCT((OFFSET(D6,-R6,0,R6,1)-U6-T6*OFFSET(E6,-R6,0,R6,1)-S6*OFFSET(F6,-R6,0,R6,1))^2)/(R6-3)),"") | W6: =IF(AND(F6>=1,R6>=Inputs!$B$10),(D6-U6-T6*E6-S6*F6)/V6,"") | X6: =IF(AB5<>0,AC5+1,0) -> 0 | Y6: =IF(W6="",0,IF(AND(AB5<>0,OR(ABS(W6)>Inputs!$B$7,X6>=Inputs!$B$8,ABS(W6)<Inputs!$B$6)),1,0)) -> 0 | Z6: =IF(Y6=1,0,AB5) -> 0 | AA6: =IF(W6="",0,IF(AND(Z6=0,ABS(W6)>Inputs!$B$5,ABS(W6)<=Inputs!$B$7),1,0)) -> 0 | AB6: =IF(W6="",0,IF(AA6=1,-SIGN(W6),Z6)) -> 0 | AC6: =IF(W6="",0,IF(AA6=1,0,IF(Y6=1,0,X6))) -> 0 | AD6: =IF(AB6=0,0,IF(AB5=AB6,AD5,T6)) -> 0 | AE6: =AB6-AB5 -> 0 | AF6: =-AD6*AB6 -> 0 | AG6: =AF6-AF5 -> 0 | AH6: =MAX(AE6,0)*(Inputs!$B$17+Inputs!$B$18+Inputs!$B$19)+MAX(-AE6,0)*(O6+Inputs!$B$18+Inputs!$B$19)+IF(AND(K6=1,AB6<>0),(Inputs!$B$17+Inputs!$B$18+Inputs!$B$19)+(O6+Inputs!$B$18+Inputs!$B$19),0)+MAX(AG6,0)*(Inputs!$B$20+Inputs!$B$22+Inputs!$B$23)+MAX(-AG6,0)*(Inputs!$B$21+Inputs!$B$22+Inputs!$B$23) -> 0 | AI6: =AB5*(M6-AD5*J6)+AB5*AD5*N6/Inputs!$B$16-AH6 -> 0 | AJ6: =MAX(AE6,0)*(Inputs!$B$17+Inputs!$B$24+Inputs!$B$25)+MAX(-AE6,0)*(O6+Inputs!$B$24+Inputs!$B$25)+IF(AND(K6=1,AB6<>0),(Inputs!$B$17+Inputs!$B$24+Inputs!$B$25)+(O6+Inputs!$B$24+Inputs!$B$25),0)+MAX(AG6,0)*(Inputs!$B$20+Inputs!$B$26+Inputs!$B$27)+MAX(-AG6,0)*(Inputs!$B$21+Inputs!$B$26+Inputs!$B$27) -> 0 | AK6: =AB5*(M6-AD5*J6)+AB5*AD5*(N6+Inputs!$B$14)/Inputs!$B$16-AJ6 -> 0 | AL6: =IF(AP5<>0,AQ5+1,0) -> 0 | AM6: =IF(W6="",0,IF(AND(AP5<>0,OR(ABS(W6)>Inputs!$B$7,AL6>=Inputs!$B$8,ABS(W6)<Inputs!$B$6)),1,0)) -> 0 | AN6: =IF(AM6=1,0,AP5) -> 0 | AO6: =IF(W6="",0,IF(AND(AN6=0,ABS(W6)>Inputs!$B$5,ABS(W6)<=Inputs!$B$7,W6>0),1,0)) -> 0 | AP6: =IF(W6="",0,IF(AO6=1,-SIGN(W6),AN6)) -> 0 | AQ6: =IF(W6="",0,IF(AO6=1,0,IF(AM6=1,0,AL6))) -> 0 | AR6: =IF(AP6=0,0,IF(AP5=AP6,AR5,T6)) -> 0 | AS6: =AP6-AP5 -> 0 | AT6: =-AR6*AP6 -> 0 | AU6: =AT6-AT5 -> 0 | AV6: =MAX(AS6,0)*(Inputs!$B$17+Inputs!$B$18+Inputs!$B$19)+MAX(-AS6,0)*(O6+Inputs!$B$18+Inputs!$B$19)+IF(AND(K6=1,AP6<>0),(Inputs!$B$17+Inputs!$B$18+Inputs!$B$19)+(O6+Inputs!$B$18+Inputs!$B$19),0)+MAX(AU6,0)*(Inputs!$B$20+Inputs!$B$22+Inputs!$B$23)+MAX(-AU6,0)*(Inputs!$B$21+Inputs!$B$22+Inputs!$B$23) -> 0 | AW6: =AP5*(M6-AR5*J6)+AP5*AR5*N6/Inputs!$B$16-AV6 -> 0 | AX6: =AW6-IF(AP5<>0,0.75*AR5*(Inputs!$B$13-N6)/Inputs!$B$16,0) -> 0 | AY6: =MAX(AS6,0)*(Inputs!$B$17+Inputs!$B$18+Inputs!$B$19)+MAX(-AS6,0)*(O6+Inputs!$B$18+Inputs!$B$19)+IF(AND(K6=1,AP6<>0),(Inputs!$B$17+Inputs!$B$18+Inputs!$B$19)+(O6+Inputs!$B$18+Inputs!$B$19),0) -> 0 | AZ6: =AP5*M6-AY6 -> 0 | BA6: =BA5+AI6 -> 0 | BB6: =MAX(BB5,BA6) -> 0 | BC6: =BA6-BB6 -> 0 | BD6: =A7-A6 -> 1
A7: 45050 | B7: 18287 | C7: 199.36 | D7: =LN(B7) -> 9.8139457 | E7: =LN(C7) -> 5.2951122 | F7: 2 | G7: 21 | H7: =D7-E7 -> 4.5188335 | I7: =D7-D6 -> 0.0076686356 | J7: =E7-E6 -> 0.00896867 | K7: 0 | L7: 0 | M7: =IF(L7=1,J7-Carry!$B$9/Inputs!$B$16,I7) -> 0.0076686356 | N7: 0.065 | O7: 0.000125 | P7: =D7-('2 Hedge ratio'!$B$6+'2 Hedge ratio'!$B$5*E7) -> 0.0011316103 | Q7: =D7-('5 Re-specification'!$B$7+'5 Re-specification'!$B$5*E7+'5 Re-specification'!$B$6*F7) -> 0.0037691437 | R7: =MIN(F7,Inputs!$B$9) -> 2 | S7: =IF(AND(F7>=1,R7>=Inputs!$B$10),INDEX(LINEST(OFFSET(D7,-R7,0,R7,1),OFFSET(E7,-R7,0,R7,2)),1,1),"") | T7: =IF(AND(F7>=1,R7>=Inputs!$B$10),INDEX(LINEST(OFFSET(D7,-R7,0,R7,1),OFFSET(E7,-R7,0,R7,2)),1,2),"") | U7: =IF(AND(F7>=1,R7>=Inputs!$B$10),INDEX(LINEST(OFFSET(D7,-R7,0,R7,1),OFFSET(E7,-R7,0,R7,2)),1,3),"") | V7: =IF(AND(F7>=1,R7>=Inputs!$B$10),SQRT(SUMPRODUCT((OFFSET(D7,-R7,0,R7,1)-U7-T7*OFFSET(E7,-R7,0,R7,1)-S7*OFFSET(F7,-R7,0,R7,1))^2)/(R7-3)),"") | W7: =IF(AND(F7>=1,R7>=Inputs!$B$10),(D7-U7-T7*E7-S7*F7)/V7,"") | X7: =IF(AB6<>0,AC6+1,0) -> 0 | Y7: =IF(W7="",0,IF(AND(AB6<>0,OR(ABS(W7)>Inputs!$B$7,X7>=Inputs!$B$8,ABS(W7)<Inputs!$B$6)),1,0)) -> 0 | Z7: =IF(Y7=1,0,AB6) -> 0 | AA7: =IF(W7="",0,IF(AND(Z7=0,ABS(W7)>Inputs!$B$5,ABS(W7)<=Inputs!$B$7),1,0)) -> 0 | AB7: =IF(W7="",0,IF(AA7=1,-SIGN(W7),Z7)) -> 0 | AC7: =IF(W7="",0,IF(AA7=1,0,IF(Y7=1,0,X7))) -> 0 | AD7: =IF(AB7=0,0,IF(AB6=AB7,AD6,T7)) -> 0 | AE7: =AB7-AB6 -> 0 | AF7: =-AD7*AB7 -> 0 | AG7: =AF7-AF6 -> 0 | AH7: =MAX(AE7,0)*(Inputs!$B$17+Inputs!$B$18+Inputs!$B$19)+MAX(-AE7,0)*(O7+Inputs!$B$18+Inputs!$B$19)+IF(AND(K7=1,AB7<>0),(Inputs!$B$17+Inputs!$B$18+Inputs!$B$19)+(O7+Inputs!$B$18+Inputs!$B$19),0)+MAX(AG7,0)*(Inputs!$B$20+Inputs!$B$22+Inputs!$B$23)+MAX(-AG7,0)*(Inputs!$B$21+Inputs!$B$22+Inputs!$B$23) -> 0 | AI7: =AB6*(M7-AD6*J7)+AB6*AD6*N7/Inputs!$B$16-AH7 -> 0 | AJ7: =MAX(AE7,0)*(Inputs!$B$17+Inputs!$B$24+Inputs!$B$25)+MAX(-AE7,0)*(O7+Inputs!$B$24+Inputs!$B$25)+IF(AND(K7=1,AB7<>0),(Inputs!$B$17+Inputs!$B$24+Inputs!$B$25)+(O7+Inputs!$B$24+Inputs!$B$25),0)+MAX(AG7,0)*(Inputs!$B$20+Inputs!$B$26+Inputs!$B$27)+MAX(-AG7,0)*(Inputs!$B$21+Inputs!$B$26+Inputs!$B$27) -> 0 | AK7: =AB6*(M7-AD6*J7)+AB6*AD6*(N7+Inputs!$B$14)/Inputs!$B$16-AJ7 -> 0 | AL7: =IF(AP6<>0,AQ6+1,0) -> 0 | AM7: =IF(W7="",0,IF(AND(AP6<>0,OR(ABS(W7)>Inputs!$B$7,AL7>=Inputs!$B$8,ABS(W7)<Inputs!$B$6)),1,0)) -> 0 | AN7: =IF(AM7=1,0,AP6) -> 0 | AO7: =IF(W7="",0,IF(AND(AN7=0,ABS(W7)>Inputs!$B$5,ABS(W7)<=Inputs!$B$7,W7>0),1,0)) -> 0 | AP7: =IF(W7="",0,IF(AO7=1,-SIGN(W7),AN7)) -> 0 | AQ7: =IF(W7="",0,IF(AO7=1,0,IF(AM7=1,0,AL7))) -> 0 | AR7: =IF(AP7=0,0,IF(AP6=AP7,AR6,T7)) -> 0 | AS7: =AP7-AP6 -> 0 | AT7: =-AR7*AP7 -> 0 | AU7: =AT7-AT6 -> 0 | AV7: =MAX(AS7,0)*(Inputs!$B$17+Inputs!$B$18+Inputs!$B$19)+MAX(-AS7,0)*(O7+Inputs!$B$18+Inputs!$B$19)+IF(AND(K7=1,AP7<>0),(Inputs!$B$17+Inputs!$B$18+Inputs!$B$19)+(O7+Inputs!$B$18+Inputs!$B$19),0)+MAX(AU7,0)*(Inputs!$B$20+Inputs!$B$22+Inputs!$B$23)+MAX(-AU7,0)*(Inputs!$B$21+Inputs!$B$22+Inputs!$B$23) -> 0 | AW7: =AP6*(M7-AR6*J7)+AP6*AR6*N7/Inputs!$B$16-AV7 -> 0 | AX7: =AW7-IF(AP6<>0,0.75*AR6*(Inputs!$B$13-N7)/Inputs!$B$16,0) -> 0 | AY7: =MAX(AS7,0)*(Inputs!$B$17+Inputs!$B$18+Inputs!$B$19)+MAX(-AS7,0)*(O7+Inputs!$B$18+Inputs!$B$19)+IF(AND(K7=1,AP7<>0),(Inputs!$B$17+Inputs!$B$18+Inputs!$B$19)+(O7+Inputs!$B$18+Inputs!$B$19),0) -> 0 | AZ7: =AP6*M7-AY7 -> 0 | BA7: =BA6+AI7 -> 0 | BB7: =MAX(BB6,BA7) -> 0 | BC7: =BA7-BB7 -> 0 | BD7: =A8-A7 -> 1
A8: 45051 | B8: 18130.1 | C8: 197.89 | D8: =LN(B8) -> 9.8053288 | E8: =LN(C8) -> 5.2877113 | F8: 3 | G8: 20 | H8: =D8-E8 -> 4.5176175 | I8: =D8-D7 -> -0.0086168844 | J8: =E8-E7 -> -0.0074009148 | K8: 0 | L8: 0 | M8: =IF(L8=1,J8-Carry!$B$9/Inputs!$B$16,I8) -> -0.0086168844 | N8: 0.065 | O8: 0.000125 | P8: =D8-('2 Hedge ratio'!$B$6+'2 Hedge ratio'!$B$5*E8) -> -0.00070509802 | Q8: =D8-('5 Re-specification'!$B$7+'5 Re-specification'!$B$5*E8+'5 Re-specification'!$B$6*F8) -> 0.002575675 | R8: =MIN(F8,Inputs!$B$9) -> 3 | S8: =IF(AND(F8>=1,R8>=Inputs!$B$10),INDEX(LINEST(OFFSET(D8,-R8,0,R8,1),OFFSET(E8,-R8,0,R8,2)),1,1),"") | T8: =IF(AND(F8>=1,R8>=Inputs!$B$10),INDEX(LINEST(OFFSET(D8,-R8,0,R8,1),OFFSET(E8,-R8,0,R8,2)),1,2),"") | U8: =IF(AND(F8>=1,R8>=Inputs!$B$10),INDEX(LINEST(OFFSET(D8,-R8,0,R8,1),OFFSET(E8,-R8,0,R8,2)),1,3),"") | V8: =IF(AND(F8>=1,R8>=Inputs!$B$10),SQRT(SUMPRODUCT((OFFSET(D8,-R8,0,R8,1)-U8-T8*OFFSET(E8,-R8,0,R8,1)-S8*OFFSET(F8,-R8,0,R8,1))^2)/(R8-3)),"") | W8: =IF(AND(F8>=1,R8>=Inputs!$B$10),(D8-U8-T8*E8-S8*F8)/V8,"") | X8: =IF(AB7<>0,AC7+1,0) -> 0 | Y8: =IF(W8="",0,IF(AND(AB7<>0,OR(ABS(W8)>Inputs!$B$7,X8>=Inputs!$B$8,ABS(W8)<Inputs!$B$6)),1,0)) -> 0 | Z8: =IF(Y8=1,0,AB7) -> 0 | AA8: =IF(W8="",0,IF(AND(Z8=0,ABS(W8)>Inputs!$B$5,ABS(W8)<=Inputs!$B$7),1,0)) -> 0 | AB8: =IF(W8="",0,IF(AA8=1,-SIGN(W8),Z8)) -> 0 | AC8: =IF(W8="",0,IF(AA8=1,0,IF(Y8=1,0,X8))) -> 0 | AD8: =IF(AB8=0,0,IF(AB7=AB8,AD7,T8)) -> 0 | AE8: =AB8-AB7 -> 0 | AF8: =-AD8*AB8 -> 0 | AG8: =AF8-AF7 -> 0 | AH8: =MAX(AE8,0)*(Inputs!$B$17+Inputs!$B$18+Inputs!$B$19)+MAX(-AE8,0)*(O8+Inputs!$B$18+Inputs!$B$19)+IF(AND(K8=1,AB8<>0),(Inputs!$B$17+Inputs!$B$18+Inputs!$B$19)+(O8+Inputs!$B$18+Inputs!$B$19),0)+MAX(AG8,0)*(Inputs!$B$20+Inputs!$B$22+Inputs!$B$23)+MAX(-AG8,0)*(Inputs!$B$21+Inputs!$B$22+Inputs!$B$23) -> 0 | AI8: =AB7*(M8-AD7*J8)+AB7*AD7*N8/Inputs!$B$16-AH8 -> 0 | AJ8: =MAX(AE8,0)*(Inputs!$B$17+Inputs!$B$24+Inputs!$B$25)+MAX(-AE8,0)*(O8+Inputs!$B$24+Inputs!$B$25)+IF(AND(K8=1,AB8<>0),(Inputs!$B$17+Inputs!$B$24+Inputs!$B$25)+(O8+Inputs!$B$24+Inputs!$B$25),0)+MAX(AG8,0)*(Inputs!$B$20+Inputs!$B$26+Inputs!$B$27)+MAX(-AG8,0)*(Inputs!$B$21+Inputs!$B$26+Inputs!$B$27) -> 0 | AK8: =AB7*(M8-AD7*J8)+AB7*AD7*(N8+Inputs!$B$14)/Inputs!$B$16-AJ8 -> 0 | AL8: =IF(AP7<>0,AQ7+1,0) -> 0 | AM8: =IF(W8="",0,IF(AND(AP7<>0,OR(ABS(W8)>Inputs!$B$7,AL8>=Inputs!$B$8,ABS(W8)<Inputs!$B$6)),1,0)) -> 0 | AN8: =IF(AM8=1,0,AP7) -> 0 | AO8: =IF(W8="",0,IF(AND(AN8=0,ABS(W8)>Inputs!$B$5,ABS(W8)<=Inputs!$B$7,W8>0),1,0)) -> 0 | AP8: =IF(W8="",0,IF(AO8=1,-SIGN(W8),AN8)) -> 0 | AQ8: =IF(W8="",0,IF(AO8=1,0,IF(AM8=1,0,AL8))) -> 0 | AR8: =IF(AP8=0,0,IF(AP7=AP8,AR7,T8)) -> 0 | AS8: =AP8-AP7 -> 0 | AT8: =-AR8*AP8 -> 0 | AU8: =AT8-AT7 -> 0 | AV8: =MAX(AS8,0)*(Inputs!$B$17+Inputs!$B$18+Inputs!$B$19)+MAX(-AS8,0)*(O8+Inputs!$B$18+Inputs!$B$19)+IF(AND(K8=1,AP8<>0),(Inputs!$B$17+Inputs!$B$18+Inputs!$B$19)+(O8+Inputs!$B$18+Inputs!$B$19),0)+MAX(AU8,0)*(Inputs!$B$20+Inputs!$B$22+Inputs!$B$23)+MAX(-AU8,0)*(Inputs!$B$21+Inputs!$B$22+Inputs!$B$23) -> 0 | AW8: =AP7*(M8-AR7*J8)+AP7*AR7*N8/Inputs!$B$16-AV8 -> 0 | AX8: =AW8-IF(AP7<>0,0.75*AR7*(Inputs!$B$13-N8)/Inputs!$B$16,0) -> 0 | AY8: =MAX(AS8,0)*(Inputs!$B$17+Inputs!$B$18+Inputs!$B$19)+MAX(-AS8,0)*(O8+Inputs!$B$18+Inputs!$B$19)+IF(AND(K8=1,AP8<>0),(Inputs!$B$17+Inputs!$B$18+Inputs!$B$19)+(O8+Inputs!$B$18+Inputs!$B$19),0) -> 0 | AZ8: =AP7*M8-AY8 -> 0 | BA8: =BA7+AI8 -> 0 | BB8: =MAX(BB7,BA8) -> 0 | BC8: =BA8-BB8 -> 0 | BD8: =A9-A8 -> 3
A9: 45054 | B9: 18317.5 | C9: 199.9 | D9: =LN(B9) -> 9.8156122 | E9: =LN(C9) -> 5.2978172 | F9: 4 | G9: 17 | H9: =D9-E9 -> 4.5177949 | I9: =D9-D8 -> 0.010283347 | J9: =E9-E8 -> 0.010105921 | K9: 0 | L9: 0 | M9: =IF(L9=1,J9-Carry!$B$9/Inputs!$B$16,I9) -> 0.010283347 | N9: 0.065 | O9: 0.000125 | P9: =D9-('2 Hedge ratio'!$B$6+'2 Hedge ratio'!$B$5*E9) -> 0.00031994414 | Q9: =D9-('5 Re-specification'!$B$7+'5 Re-specification'!$B$5*E9+'5 Re-specification'!$B$6*F9) -> 0.0028286561 | R9: =MIN(F9,Inputs!$B$9) -> 4 | S9: =IF(AND(F9>=1,R9>=Inputs!$B$10),INDEX(LINEST(OFFSET(D9,-R9,0,R9,1),OFFSET(E9,-R9,0,R9,2)),1,1),"") | T9: =IF(AND(F9>=1,R9>=Inputs!$B$10),INDEX(LINEST(OFFSET(D9,-R9,0,R9,1),OFFSET(E9,-R9,0,R9,2)),1,2),"") | U9: =IF(AND(F9>=1,R9>=Inputs!$B$10),INDEX(LINEST(OFFSET(D9,-R9,0,R9,1),OFFSET(E9,-R9,0,R9,2)),1,3),"") | V9: =IF(AND(F9>=1,R9>=Inputs!$B$10),SQRT(SUMPRODUCT((OFFSET(D9,-R9,0,R9,1)-U9-T9*OFFSET(E9,-R9,0,R9,1)-S9*OFFSET(F9,-R9,0,R9,1))^2)/(R9-3)),"") | W9: =IF(AND(F9>=1,R9>=Inputs!$B$10),(D9-U9-T9*E9-S9*F9)/V9,"") | X9: =IF(AB8<>0,AC8+1,0) -> 0 | Y9: =IF(W9="",0,IF(AND(AB8<>0,OR(ABS(W9)>Inputs!$B$7,X9>=Inputs!$B$8,ABS(W9)<Inputs!$B$6)),1,0)) -> 0 | Z9: =IF(Y9=1,0,AB8) -> 0 | AA9: =IF(W9="",0,IF(AND(Z9=0,ABS(W9)>Inputs!$B$5,ABS(W9)<=Inputs!$B$7),1,0)) -> 0 | AB9: =IF(W9="",0,IF(AA9=1,-SIGN(W9),Z9)) -> 0 | AC9: =IF(W9="",0,IF(AA9=1,0,IF(Y9=1,0,X9))) -> 0 | AD9: =IF(AB9=0,0,IF(AB8=AB9,AD8,T9)) -> 0 | AE9: =AB9-AB8 -> 0 | AF9: =-AD9*AB9 -> 0 | AG9: =AF9-AF8 -> 0 | AH9: =MAX(AE9,0)*(Inputs!$B$17+Inputs!$B$18+Inputs!$B$19)+MAX(-AE9,0)*(O9+Inputs!$B$18+Inputs!$B$19)+IF(AND(K9=1,AB9<>0),(Inputs!$B$17+Inputs!$B$18+Inputs!$B$19)+(O9+Inputs!$B$18+Inputs!$B$19),0)+MAX(AG9,0)*(Inputs!$B$20+Inputs!$B$22+Inputs!$B$23)+MAX(-AG9,0)*(Inputs!$B$21+Inputs!$B$22+Inputs!$B$23) -> 0 | AI9: =AB8*(M9-AD8*J9)+AB8*AD8*N9/Inputs!$B$16-AH9 -> 0 | AJ9: =MAX(AE9,0)*(Inputs!$B$17+Inputs!$B$24+Inputs!$B$25)+MAX(-AE9,0)*(O9+Inputs!$B$24+Inputs!$B$25)+IF(AND(K9=1,AB9<>0),(Inputs!$B$17+Inputs!$B$24+Inputs!$B$25)+(O9+Inputs!$B$24+Inputs!$B$25),0)+MAX(AG9,0)*(Inputs!$B$20+Inputs!$B$26+Inputs!$B$27)+MAX(-AG9,0)*(Inputs!$B$21+Inputs!$B$26+Inputs!$B$27) -> 0 | AK9: =AB8*(M9-AD8*J9)+AB8*AD8*(N9+Inputs!$B$14)/Inputs!$B$16-AJ9 -> 0 | AL9: =IF(AP8<>0,AQ8+1,0) -> 0 | AM9: =IF(W9="",0,IF(AND(AP8<>0,OR(ABS(W9)>Inputs!$B$7,AL9>=Inputs!$B$8,ABS(W9)<Inputs!$B$6)),1,0)) -> 0 | AN9: =IF(AM9=1,0,AP8) -> 0 | AO9: =IF(W9="",0,IF(AND(AN9=0,ABS(W9)>Inputs!$B$5,ABS(W9)<=Inputs!$B$7,W9>0),1,0)) -> 0 | AP9: =IF(W9="",0,IF(AO9=1,-SIGN(W9),AN9)) -> 0 | AQ9: =IF(W9="",0,IF(AO9=1,0,IF(AM9=1,0,AL9))) -> 0 | AR9: =IF(AP9=0,0,IF(AP8=AP9,AR8,T9)) -> 0 | AS9: =AP9-AP8 -> 0 | AT9: =-AR9*AP9 -> 0 | AU9: =AT9-AT8 -> 0 | AV9: =MAX(AS9,0)*(Inputs!$B$17+Inputs!$B$18+Inputs!$B$19)+MAX(-AS9,0)*(O9+Inputs!$B$18+Inputs!$B$19)+IF(AND(K9=1,AP9<>0),(Inputs!$B$17+Inputs!$B$18+Inputs!$B$19)+(O9+Inputs!$B$18+Inputs!$B$19),0)+MAX(AU9,0)*(Inputs!$B$20+Inputs!$B$22+Inputs!$B$23)+MAX(-AU9,0)*(Inputs!$B$21+Inputs!$B$22+Inputs!$B$23) -> 0 | AW9: =AP8*(M9-AR8*J9)+AP8*AR8*N9/Inputs!$B$16-AV9 -> 0 | AX9: =AW9-IF(AP8<>0,0.75*AR8*(Inputs!$B$13-N9)/Inputs!$B$16,0) -> 0 | AY9: =MAX(AS9,0)*(Inputs!$B$17+Inputs!$B$18+Inputs!$B$19)+MAX(-AS9,0)*(O9+Inputs!$B$18+Inputs!$B$19)+IF(AND(K9=1,AP9<>0),(Inputs!$B$17+Inputs!$B$18+Inputs!$B$19)+(O9+Inputs!$B$18+Inputs!$B$19),0) -> 0 | AZ9: =AP8*M9-AY9 -> 0 | BA9: =BA8+AI9 -> 0 | BB9: =MAX(BB8,BA9) -> 0 | BC9: =BA9-BB9 -> 0 | BD9: =A10-A9 -> 1
A10: 45055 | B10: 18303.8 | C10: 199.75 | D10: =LN(B10) -> 9.814864 | E10: =LN(C10) -> 5.2970666 | F10: 5 | G10: 16 | H10: =D10-E10 -> 4.5177974 | I10: =D10-D9 -> -0.00074819849 | J10: =E10-E9 -> -0.00075065686 | K10: 0 | L10: 0 | M10: =IF(L10=1,J10-Carry!$B$9/Inputs!$B$16,I10) -> -0.00074819849 | N10: 0.065 | O10: 0.000125 | P10: =D10-('2 Hedge ratio'!$B$6+'2 Hedge ratio'!$B$5*E10) -> 0.00025944249 | Q10: =D10-('5 Re-specification'!$B$7+'5 Re-specification'!$B$5*E10+'5 Re-specification'!$B$6*F10) -> 0.0028737689 | R10: =MIN(F10,Inputs!$B$9) -> 5 | S10: =IF(AND(F10>=1,R10>=Inputs!$B$10),INDEX(LINEST(OFFSET(D10,-R10,0,R10,1),OFFSET(E10,-R10,0,R10,2)),1,1),"") | T10: =IF(AND(F10>=1,R10>=Inputs!$B$10),INDEX(LINEST(OFFSET(D10,-R10,0,R10,1),OFFSET(E10,-R10,0,R10,2)),1,2),"") | U10: =IF(AND(F10>=1,R10>=Inputs!$B$10),INDEX(LINEST(OFFSET(D10,-R10,0,R10,1),OFFSET(E10,-R10,0,R10,2)),1,3),"") | V10: =IF(AND(F10>=1,R10>=Inputs!$B$10),SQRT(SUMPRODUCT((OFFSET(D10,-R10,0,R10,1)-U10-T10*OFFSET(E10,-R10,0,R10,1)-S10*OFFSET(F10,-R10,0,R10,1))^2)/(R10-3)),"") | W10: =IF(AND(F10>=1,R10>=Inputs!$B$10),(D10-U10-T10*E10-S10*F10)/V10,"") | X10: =IF(AB9<>0,AC9+1,0) -> 0 | Y10: =IF(W10="",0,IF(AND(AB9<>0,OR(ABS(W10)>Inputs!$B$7,X10>=Inputs!$B$8,ABS(W10)<Inputs!$B$6)),1,0)) -> 0 | Z10: =IF(Y10=1,0,AB9) -> 0 | AA10: =IF(W10="",0,IF(AND(Z10=0,ABS(W10)>Inputs!$B$5,ABS(W10)<=Inputs!$B$7),1,0)) -> 0 | AB10: =IF(W10="",0,IF(AA10=1,-SIGN(W10),Z10)) -> 0 | AC10: =IF(W10="",0,IF(AA10=1,0,IF(Y10=1,0,X10))) -> 0 | AD10: =IF(AB10=0,0,IF(AB9=AB10,AD9,T10)) -> 0 | AE10: =AB10-AB9 -> 0 | AF10: =-AD10*AB10 -> 0 | AG10: =AF10-AF9 -> 0 | AH10: =MAX(AE10,0)*(Inputs!$B$17+Inputs!$B$18+Inputs!$B$19)+MAX(-AE10,0)*(O10+Inputs!$B$18+Inputs!$B$19)+IF(AND(K10=1,AB10<>0),(Inputs!$B$17+Inputs!$B$18+Inputs!$B$19)+(O10+Inputs!$B$18+Inputs!$B$19),0)+MAX(AG10,0)*(Inputs!$B$20+Inputs!$B$22+Inputs!$B$23)+MAX(-AG10,0)*(Inputs!$B$21+Inputs!$B$22+Inputs!$B$23) -> 0 | AI10: =AB9*(M10-AD9*J10)+AB9*AD9*N10/Inputs!$B$16-AH10 -> 0 | AJ10: =MAX(AE10,0)*(Inputs!$B$17+Inputs!$B$24+Inputs!$B$25)+MAX(-AE10,0)*(O10+Inputs!$B$24+Inputs!$B$25)+IF(AND(K10=1,AB10<>0),(Inputs!$B$17+Inputs!$B$24+Inputs!$B$25)+(O10+Inputs!$B$24+Inputs!$B$25),0)+MAX(AG10,0)*(Inputs!$B$20+Inputs!$B$26+Inputs!$B$27)+MAX(-AG10,0)*(Inputs!$B$21+Inputs!$B$26+Inputs!$B$27) -> 0 | AK10: =AB9*(M10-AD9*J10)+AB9*AD9*(N10+Inputs!$B$14)/Inputs!$B$16-AJ10 -> 0 | AL10: =IF(AP9<>0,AQ9+1,0) -> 0 | AM10: =IF(W10="",0,IF(AND(AP9<>0,OR(ABS(W10)>Inputs!$B$7,AL10>=Inputs!$B$8,ABS(W10)<Inputs!$B$6)),1,0)) -> 0 | AN10: =IF(AM10=1,0,AP9) -> 0 | AO10: =IF(W10="",0,IF(AND(AN10=0,ABS(W10)>Inputs!$B$5,ABS(W10)<=Inputs!$B$7,W10>0),1,0)) -> 0 | AP10: =IF(W10="",0,IF(AO10=1,-SIGN(W10),AN10)) -> 0 | AQ10: =IF(W10="",0,IF(AO10=1,0,IF(AM10=1,0,AL10))) -> 0 | AR10: =IF(AP10=0,0,IF(AP9=AP10,AR9,T10)) -> 0 | AS10: =AP10-AP9 -> 0 | AT10: =-AR10*AP10 -> 0 | AU10: =AT10-AT9 -> 0 | AV10: =MAX(AS10,0)*(Inputs!$B$17+Inputs!$B$18+Inputs!$B$19)+MAX(-AS10,0)*(O10+Inputs!$B$18+Inputs!$B$19)+IF(AND(K10=1,AP10<>0),(Inputs!$B$17+Inputs!$B$18+Inputs!$B$19)+(O10+Inputs!$B$18+Inputs!$B$19),0)+MAX(AU10,0)*(Inputs!$B$20+Inputs!$B$22+Inputs!$B$23)+MAX(-AU10,0)*(Inputs!$B$21+Inputs!$B$22+Inputs!$B$23) -> 0 | AW10: =AP9*(M10-AR9*J10)+AP9*AR9*N10/Inputs!$B$16-AV10 -> 0 | AX10: =AW10-IF(AP9<>0,0.75*AR9*(Inputs!$B$13-N10)/Inputs!$B$16,0) -> 0 | AY10: =MAX(AS10,0)*(Inputs!$B$17+Inputs!$B$18+Inputs!$B$19)+MAX(-AS10,0)*(O10+Inputs!$B$18+Inputs!$B$19)+IF(AND(K10=1,AP10<>0),(Inputs!$B$17+Inputs!$B$18+Inputs!$B$19)+(O10+Inputs!$B$18+Inputs!$B$19),0) -> 0 | AZ10: =AP9*M10-AY10 -> 0 | BA10: =BA9+AI10 -> 0 | BB10: =MAX(BB9,BA10) -> 0 | BC10: =BA10-BB10 -> 0 | BD10: =A11-A10 -> 1
A11: 45056 | B11: 18343 | C11: 200.21 | D11: =LN(B11) -> 9.8170033 | E11: =LN(C11) -> 5.2993668 | F11: 6 | G11: 15 | H11: =D11-E11 -> 4.5176365 | I11: =D11-D10 -> 0.0021393418 | J11: =E11-E10 -> 0.002300231 | K11: 0 | L11: 0 | M11: =IF(L11=1,J11-Carry!$B$9/Inputs!$B$16,I11) -> 0.0021393418 | N11: 0.065 | O11: 0.000125 | P11: =D11-('2 Hedge ratio'!$B$6+'2 Hedge ratio'!$B$5*E11) -> 0.00029148105 | Q11: =D11-('5 Re-specification'!$B$7+'5 Re-specification'!$B$5*E11+'5 Re-specification'!$B$6*F11) -> 0.0027647798 | R11: =MIN(F11,Inputs!$B$9) -> 6 | S11: =IF(AND(F11>=1,R11>=Inputs!$B$10),INDEX(LINEST(OFFSET(D11,-R11,0,R11,1),OFFSET(E11,-R11,0,R11,2)),1,1),"") | T11: =IF(AND(F11>=1,R11>=Inputs!$B$10),INDEX(LINEST(OFFSET(D11,-R11,0,R11,1),OFFSET(E11,-R11,0,R11,2)),1,2),"") | U11: =IF(AND(F11>=1,R11>=Inputs!$B$10),INDEX(LINEST(OFFSET(D11,-R11,0,R11,1),OFFSET(E11,-R11,0,R11,2)),1,3),"") | V11: =IF(AND(F11>=1,R11>=Inputs!$B$10),SQRT(SUMPRODUCT((OFFSET(D11,-R11,0,R11,1)-U11-T11*OFFSET(E11,-R11,0,R11,1)-S11*OFFSET(F11,-R11,0,R11,1))^2)/(R11-3)),"") | W11: =IF(AND(F11>=1,R11>=Inputs!$B$10),(D11-U11-T11*E11-S11*F11)/V11,"") | X11: =IF(AB10<>0,AC10+1,0) -> 0 | Y11: =IF(W11="",0,IF(AND(AB10<>0,OR(ABS(W11)>Inputs!$B$7,X11>=Inputs!$B$8,ABS(W11)<Inputs!$B$6)),1,0)) -> 0 | Z11: =IF(Y11=1,0,AB10) -> 0 | AA11: =IF(W11="",0,IF(AND(Z11=0,ABS(W11)>Inputs!$B$5,ABS(W11)<=Inputs!$B$7),1,0)) -> 0 | AB11: =IF(W11="",0,IF(AA11=1,-SIGN(W11),Z11)) -> 0 | AC11: =IF(W11="",0,IF(AA11=1,0,IF(Y11=1,0,X11))) -> 0 | AD11: =IF(AB11=0,0,IF(AB10=AB11,AD10,T11)) -> 0 | AE11: =AB11-AB10 -> 0 | AF11: =-AD11*AB11 -> 0 | AG11: =AF11-AF10 -> 0 | AH11: =MAX(AE11,0)*(Inputs!$B$17+Inputs!$B$18+Inputs!$B$19)+MAX(-AE11,0)*(O11+Inputs!$B$18+Inputs!$B$19)+IF(AND(K11=1,AB11<>0),(Inputs!$B$17+Inputs!$B$18+Inputs!$B$19)+(O11+Inputs!$B$18+Inputs!$B$19),0)+MAX(AG11,0)*(Inputs!$B$20+Inputs!$B$22+Inputs!$B$23)+MAX(-AG11,0)*(Inputs!$B$21+Inputs!$B$22+Inputs!$B$23) -> 0 | AI11: =AB10*(M11-AD10*J11)+AB10*AD10*N11/Inputs!$B$16-AH11 -> 0 | AJ11: =MAX(AE11,0)*(Inputs!$B$17+Inputs!$B$24+Inputs!$B$25)+MAX(-AE11,0)*(O11+Inputs!$B$24+Inputs!$B$25)+IF(AND(K11=1,AB11<>0),(Inputs!$B$17+Inputs!$B$24+Inputs!$B$25)+(O11+Inputs!$B$24+Inputs!$B$25),0)+MAX(AG11,0)*(Inputs!$B$20+Inputs!$B$26+Inputs!$B$27)+MAX(-AG11,0)*(Inputs!$B$21+Inputs!$B$26+Inputs!$B$27) -> 0 | AK11: =AB10*(M11-AD10*J11)+AB10*AD10*(N11+Inputs!$B$14)/Inputs!$B$16-AJ11 -> 0 | AL11: =IF(AP10<>0,AQ10+1,0) -> 0 | AM11: =IF(W11="",0,IF(AND(AP10<>0,OR(ABS(W11)>Inputs!$B$7,AL11>=Inputs!$B$8,ABS(W11)<Inputs!$B$6)),1,0)) -> 0 | AN11: =IF(AM11=1,0,AP10) -> 0 | AO11: =IF(W11="",0,IF(AND(AN11=0,ABS(W11)>Inputs!$B$5,ABS(W11)<=Inputs!$B$7,W11>0),1,0)) -> 0 | AP11: =IF(W11="",0,IF(AO11=1,-SIGN(W11),AN11)) -> 0 | AQ11: =IF(W11="",0,IF(AO11=1,0,IF(AM11=1,0,AL11))) -> 0 | AR11: =IF(AP11=0,0,IF(AP10=AP11,AR10,T11)) -> 0 | AS11: =AP11-AP10 -> 0 | AT11: =-AR11*AP11 -> 0 | AU11: =AT11-AT10 -> 0 | AV11: =MAX(AS11,0)*(Inputs!$B$17+Inputs!$B$18+Inputs!$B$19)+MAX(-AS11,0)*(O11+Inputs!$B$18+Inputs!$B$19)+IF(AND(K11=1,AP11<>0),(Inputs!$B$17+Inputs!$B$18+Inputs!$B$19)+(O11+Inputs!$B$18+Inputs!$B$19),0)+MAX(AU11,0)*(Inputs!$B$20+Inputs!$B$22+Inputs!$B$23)+MAX(-AU11,0)*(Inputs!$B$21+Inputs!$B$22+Inputs!$B$23) -> 0 | AW11: =AP10*(M11-AR10*J11)+AP10*AR10*N11/Inputs!$B$16-AV11 -> 0 | AX11: =AW11-IF(AP10<>0,0.75*AR10*(Inputs!$B$13-N11)/Inputs!$B$16,0) -> 0 | AY11: =MAX(AS11,0)*(Inputs!$B$17+Inputs!$B$18+Inputs!$B$19)+MAX(-AS11,0)*(O11+Inputs!$B$18+Inputs!$B$19)+IF(AND(K11=1,AP11<>0),(Inputs!$B$17+Inputs!$B$18+Inputs!$B$19)+(O11+Inputs!$B$18+Inputs!$B$19),0) -> 0 | AZ11: =AP10*M11-AY11 -> 0 | BA11: =BA10+AI11 -> 0 | BB11: =MAX(BB10,BA11) -> 0 | BC11: =BA11-BB11 -> 0 | BD11: =A12-A11 -> 1
A12: 45057 | B12: 18359 | C12: 200.4 | D12: =LN(B12) -> 9.8178752 | E12: =LN(C12) -> 5.3003154 | F12: 7 | G12: 14 | H12: =D12-E12 -> 4.5175598 | I12: =D12-D11 -> 0.00087188715 | J12: =E12-E11 -> 0.00094855353 | K12: 0 | L12: 0 | M12: =IF(L12=1,J12-Carry!$B$9/Inputs!$B$16,I12) -> 0.00087188715 | N12: 0.065 | O12: 0.000125 | P12: =D12-('2 Hedge ratio'!$B$6+'2 Hedge ratio'!$B$5*E12) -> 0.00029437293 | Q12: =D12-('5 Re-specification'!$B$7+'5 Re-specification'!$B$5*E12+'5 Re-specification'!$B$6*F12) -> 0.0027359174 | R12: =MIN(F12,Inputs!$B$9) -> 7 | S12: =IF(AND(F12>=1,R12>=Inputs!$B$10),INDEX(LINEST(OFFSET(D12,-R12,0,R12,1),OFFSET(E12,-R12,0,R12,2)),1,1),"") | T12: =IF(AND(F12>=1,R12>=Inputs!$B$10),INDEX(LINEST(OFFSET(D12,-R12,0,R12,1),OFFSET(E12,-R12,0,R12,2)),1,2),"") | U12: =IF(AND(F12>=1,R12>=Inputs!$B$10),INDEX(LINEST(OFFSET(D12,-R12,0,R12,1),OFFSET(E12,-R12,0,R12,2)),1,3),"") | V12: =IF(AND(F12>=1,R12>=Inputs!$B$10),SQRT(SUMPRODUCT((OFFSET(D12,-R12,0,R12,1)-U12-T12*OFFSET(E12,-R12,0,R12,1)-S12*OFFSET(F12,-R12,0,R12,1))^2)/(R12-3)),"") | W12: =IF(AND(F12>=1,R12>=Inputs!$B$10),(D12-U12-T12*E12-S12*F12)/V12,"") | X12: =IF(AB11<>0,AC11+1,0) -> 0 | Y12: =IF(W12="",0,IF(AND(AB11<>0,OR(ABS(W12)>Inputs!$B$7,X12>=Inputs!$B$8,ABS(W12)<Inputs!$B$6)),1,0)) -> 0 | Z12: =IF(Y12=1,0,AB11) -> 0 | AA12: =IF(W12="",0,IF(AND(Z12=0,ABS(W12)>Inputs!$B$5,ABS(W12)<=Inputs!$B$7),1,0)) -> 0 | AB12: =IF(W12="",0,IF(AA12=1,-SIGN(W12),Z12)) -> 0 | AC12: =IF(W12="",0,IF(AA12=1,0,IF(Y12=1,0,X12))) -> 0 | AD12: =IF(AB12=0,0,IF(AB11=AB12,AD11,T12)) -> 0 | AE12: =AB12-AB11 -> 0 | AF12: =-AD12*AB12 -> 0 | AG12: =AF12-AF11 -> 0 | AH12: =MAX(AE12,0)*(Inputs!$B$17+Inputs!$B$18+Inputs!$B$19)+MAX(-AE12,0)*(O12+Inputs!$B$18+Inputs!$B$19)+IF(AND(K12=1,AB12<>0),(Inputs!$B$17+Inputs!$B$18+Inputs!$B$19)+(O12+Inputs!$B$18+Inputs!$B$19),0)+MAX(AG12,0)*(Inputs!$B$20+Inputs!$B$22+Inputs!$B$23)+MAX(-AG12,0)*(Inputs!$B$21+Inputs!$B$22+Inputs!$B$23) -> 0 | AI12: =AB11*(M12-AD11*J12)+AB11*AD11*N12/Inputs!$B$16-AH12 -> 0 | AJ12: =MAX(AE12,0)*(Inputs!$B$17+Inputs!$B$24+Inputs!$B$25)+MAX(-AE12,0)*(O12+Inputs!$B$24+Inputs!$B$25)+IF(AND(K12=1,AB12<>0),(Inputs!$B$17+Inputs!$B$24+Inputs!$B$25)+(O12+Inputs!$B$24+Inputs!$B$25),0)+MAX(AG12,0)*(Inputs!$B$20+Inputs!$B$26+Inputs!$B$27)+MAX(-AG12,0)*(Inputs!$B$21+Inputs!$B$26+Inputs!$B$27) -> 0 | AK12: =AB11*(M12-AD11*J12)+AB11*AD11*(N12+Inputs!$B$14)/Inputs!$B$16-AJ12 -> 0 | AL12: =IF(AP11<>0,AQ11+1,0) -> 0 | AM12: =IF(W12="",0,IF(AND(AP11<>0,OR(ABS(W12)>Inputs!$B$7,AL12>=Inputs!$B$8,ABS(W12)<Inputs!$B$6)),1,0)) -> 0 | AN12: =IF(AM12=1,0,AP11) -> 0 | AO12: =IF(W12="",0,IF(AND(AN12=0,ABS(W12)>Inputs!$B$5,ABS(W12)<=Inputs!$B$7,W12>0),1,0)) -> 0 | AP12: =IF(W12="",0,IF(AO12=1,-SIGN(W12),AN12)) -> 0 | AQ12: =IF(W12="",0,IF(AO12=1,0,IF(AM12=1,0,AL12))) -> 0 | AR12: =IF(AP12=0,0,IF(AP11=AP12,AR11,T12)) -> 0 | AS12: =AP12-AP11 -> 0 | AT12: =-AR12*AP12 -> 0 | AU12: =AT12-AT11 -> 0 | AV12: =MAX(AS12,0)*(Inputs!$B$17+Inputs!$B$18+Inputs!$B$19)+MAX(-AS12,0)*(O12+Inputs!$B$18+Inputs!$B$19)+IF(AND(K12=1,AP12<>0),(Inputs!$B$17+Inputs!$B$18+Inputs!$B$19)+(O12+Inputs!$B$18+Inputs!$B$19),0)+MAX(AU12,0)*(Inputs!$B$20+Inputs!$B$22+Inputs!$B$23)+MAX(-AU12,0)*(Inputs!$B$21+Inputs!$B$22+Inputs!$B$23) -> 0 | AW12: =AP11*(M12-AR11*J12)+AP11*AR11*N12/Inputs!$B$16-AV12 -> 0 | AX12: =AW12-IF(AP11<>0,0.75*AR11*(Inputs!$B$13-N12)/Inputs!$B$16,0) -> 0 | AY12: =MAX(AS12,0)*(Inputs!$B$17+Inputs!$B$18+Inputs!$B$19)+MAX(-AS12,0)*(O12+Inputs!$B$18+Inputs!$B$19)+IF(AND(K12=1,AP12<>0),(Inputs!$B$17+Inputs!$B$18+Inputs!$B$19)+(O12+Inputs!$B$18+Inputs!$B$19),0) -> 0 | AZ12: =AP11*M12-AY12 -> 0 | BA12: =BA11+AI12 -> 0 | BB12: =MAX(BB11,BA12) -> 0 | BC12: =BA12-BB12 -> 0 | BD12: =A13-A12 -> 1
A13: 45058 | B13: 18334 | C13: 200.1 | D13: =LN(B13) -> 9.8165125 | E13: =LN(C13) -> 5.2988172 | F13: 8 | G13: 13 | H13: =D13-E13 -> 4.5176953 | I13: =D13-D12 -> -0.0013626579 | J13: =E13-E12 -> -0.0014981276 | K13: 0 | L13: 0 | M13: =IF(L13=1,J13-Carry!$B$9/Inputs!$B$16,I13) -> -0.0013626579 | N13: 0.065 | O13: 0.000125 | P13: =D13-('2 Hedge ratio'!$B$6+'2 Hedge ratio'!$B$5*E13) -> 0.0003041898 | Q13: =D13-('5 Re-specification'!$B$7+'5 Re-specification'!$B$5*E13+'5 Re-specification'!$B$6*F13) -> 0.0029117763 | R13: =MIN(F13,Inputs!$B$9) -> 8 | S13: =IF(AND(F13>=1,R13>=Inputs!$B$10),INDEX(LINEST(OFFSET(D13,-R13,0,R13,1),OFFSET(E13,-R13,0,R13,2)),1,1),"") | T13: =IF(AND(F13>=1,R13>=Inputs!$B$10),INDEX(LINEST(OFFSET(D13,-R13,0,R13,1),OFFSET(E13,-R13,0,R13,2)),1,2),"") | U13: =IF(AND(F13>=1,R13>=Inputs!$B$10),INDEX(LINEST(OFFSET(D13,-R13,0,R13,1),OFFSET(E13,-R13,0,R13,2)),1,3),"") | V13: =IF(AND(F13>=1,R13>=Inputs!$B$10),SQRT(SUMPRODUCT((OFFSET(D13,-R13,0,R13,1)-U13-T13*OFFSET(E13,-R13,0,R13,1)-S13*OFFSET(F13,-R13,0,R13,1))^2)/(R13-3)),"") | W13: =IF(AND(F13>=1,R13>=Inputs!$B$10),(D13-U13-T13*E13-S13*F13)/V13,"") | X13: =IF(AB12<>0,AC12+1,0) -> 0 | Y13: =IF(W13="",0,IF(AND(AB12<>0,OR(ABS(W13)>Inputs!$B$7,X13>=Inputs!$B$8,ABS(W13)<Inputs!$B$6)),1,0)) -> 0 | Z13: =IF(Y13=1,0,AB12) -> 0 | AA13: =IF(W13="",0,IF(AND(Z13=0,ABS(W13)>Inputs!$B$5,ABS(W13)<=Inputs!$B$7),1,0)) -> 0 | AB13: =IF(W13="",0,IF(AA13=1,-SIGN(W13),Z13)) -> 0 | AC13: =IF(W13="",0,IF(AA13=1,0,IF(Y13=1,0,X13))) -> 0 | AD13: =IF(AB13=0,0,IF(AB12=AB13,AD12,T13)) -> 0 | AE13: =AB13-AB12 -> 0 | AF13: =-AD13*AB13 -> 0 | AG13: =AF13-AF12 -> 0 | AH13: =MAX(AE13,0)*(Inputs!$B$17+Inputs!$B$18+Inputs!$B$19)+MAX(-AE13,0)*(O13+Inputs!$B$18+Inputs!$B$19)+IF(AND(K13=1,AB13<>0),(Inputs!$B$17+Inputs!$B$18+Inputs!$B$19)+(O13+Inputs!$B$18+Inputs!$B$19),0)+MAX(AG13,0)*(Inputs!$B$20+Inputs!$B$22+Inputs!$B$23)+MAX(-AG13,0)*(Inputs!$B$21+Inputs!$B$22+Inputs!$B$23) -> 0 | AI13: =AB12*(M13-AD12*J13)+AB12*AD12*N13/Inputs!$B$16-AH13 -> 0 | AJ13: =MAX(AE13,0)*(Inputs!$B$17+Inputs!$B$24+Inputs!$B$25)+MAX(-AE13,0)*(O13+Inputs!$B$24+Inputs!$B$25)+IF(AND(K13=1,AB13<>0),(Inputs!$B$17+Inputs!$B$24+Inputs!$B$25)+(O13+Inputs!$B$24+Inputs!$B$25),0)+MAX(AG13,0)*(Inputs!$B$20+Inputs!$B$26+Inputs!$B$27)+MAX(-AG13,0)*(Inputs!$B$21+Inputs!$B$26+Inputs!$B$27) -> 0 | AK13: =AB12*(M13-AD12*J13)+AB12*AD12*(N13+Inputs!$B$14)/Inputs!$B$16-AJ13 -> 0 | AL13: =IF(AP12<>0,AQ12+1,0) -> 0 | AM13: =IF(W13="",0,IF(AND(AP12<>0,OR(ABS(W13)>Inputs!$B$7,AL13>=Inputs!$B$8,ABS(W13)<Inputs!$B$6)),1,0)) -> 0 | AN13: =IF(AM13=1,0,AP12) -> 0 | AO13: =IF(W13="",0,IF(AND(AN13=0,ABS(W13)>Inputs!$B$5,ABS(W13)<=Inputs!$B$7,W13>0),1,0)) -> 0 | AP13: =IF(W13="",0,IF(AO13=1,-SIGN(W13),AN13)) -> 0 | AQ13: =IF(W13="",0,IF(AO13=1,0,IF(AM13=1,0,AL13))) -> 0 | AR13: =IF(AP13=0,0,IF(AP12=AP13,AR12,T13)) -> 0 | AS13: =AP13-AP12 -> 0 | AT13: =-AR13*AP13 -> 0 | AU13: =AT13-AT12 -> 0 | AV13: =MAX(AS13,0)*(Inputs!$B$17+Inputs!$B$18+Inputs!$B$19)+MAX(-AS13,0)*(O13+Inputs!$B$18+Inputs!$B$19)+IF(AND(K13=1,AP13<>0),(Inputs!$B$17+Inputs!$B$18+Inputs!$B$19)+(O13+Inputs!$B$18+Inputs!$B$19),0)+MAX(AU13,0)*(Inputs!$B$20+Inputs!$B$22+Inputs!$B$23)+MAX(-AU13,0)*(Inputs!$B$21+Inputs!$B$22+Inputs!$B$23) -> 0 | AW13: =AP12*(M13-AR12*J13)+AP12*AR12*N13/Inputs!$B$16-AV13 -> 0 | AX13: =AW13-IF(AP12<>0,0.75*AR12*(Inputs!$B$13-N13)/Inputs!$B$16,0) -> 0 | AY13: =MAX(AS13,0)*(Inputs!$B$17+Inputs!$B$18+Inputs!$B$19)+MAX(-AS13,0)*(O13+Inputs!$B$18+Inputs!$B$19)+IF(AND(K13=1,AP13<>0),(Inputs!$B$17+Inputs!$B$18+Inputs!$B$19)+(O13+Inputs!$B$18+Inputs!$B$19),0) -> 0 | AZ13: =AP12*M13-AY13 -> 0 | BA13: =BA12+AI13 -> 0 | BB13: =MAX(BB12,BA13) -> 0 | BC13: =BA13-BB13 -> 0 | BD13: =A14-A13 -> 3
A14: 45061 | B14: 18408 | C14: 201.38 | D14: =LN(B14) -> 9.8205406 | E14: =LN(C14) -> 5.3051937 | F14: 9 | G14: 10 | H14: =D14-E14 -> 4.515347 | I14: =D14-D13 -> 0.0040280932 | J14: =E14-E13 -> 0.0063764289 | K14: 0 | L14: 0 | M14: =IF(L14=1,J14-Carry!$B$9/Inputs!$B$16,I14) -> 0.0040280932 | N14: 0.065 | O14: 0.000125 | P14: =D14-('2 Hedge ratio'!$B$6+'2 Hedge ratio'!$B$5*E14) -> -0.0015093342 | Q14: =D14-('5 Re-specification'!$B$7+'5 Re-specification'!$B$5*E14+'5 Re-specification'!$B$6*F14) -> 0.00062769367 | R14: =MIN(F14,Inputs!$B$9) -> 9 | S14: =IF(AND(F14>=1,R14>=Inputs!$B$10),INDEX(LINEST(OFFSET(D14,-R14,0,R14,1),OFFSET(E14,-R14,0,R14,2)),1,1),"") | T14: =IF(AND(F14>=1,R14>=Inputs!$B$10),INDEX(LINEST(OFFSET(D14,-R14,0,R14,1),OFFSET(E14,-R14,0,R14,2)),1,2),"") | U14: =IF(AND(F14>=1,R14>=Inputs!$B$10),INDEX(LINEST(OFFSET(D14,-R14,0,R14,1),OFFSET(E14,-R14,0,R14,2)),1,3),"") | V14: =IF(AND(F14>=1,R14>=Inputs!$B$10),SQRT(SUMPRODUCT((OFFSET(D14,-R14,0,R14,1)-U14-T14*OFFSET(E14,-R14,0,R14,1)-S14*OFFSET(F14,-R14,0,R14,1))^2)/(R14-3)),"") | W14: =IF(AND(F14>=1,R14>=Inputs!$B$10),(D14-U14-T14*E14-S14*F14)/V14,"") | X14: =IF(AB13<>0,AC13+1,0) -> 0 | Y14: =IF(W14="",0,IF(AND(AB13<>0,OR(ABS(W14)>Inputs!$B$7,X14>=Inputs!$B$8,ABS(W14)<Inputs!$B$6)),1,0)) -> 0 | Z14: =IF(Y14=1,0,AB13) -> 0 | AA14: =IF(W14="",0,IF(AND(Z14=0,ABS(W14)>Inputs!$B$5,ABS(W14)<=Inputs!$B$7),1,0)) -> 0 | AB14: =IF(W14="",0,IF(AA14=1,-SIGN(W14),Z14)) -> 0 | AC14: =IF(W14="",0,IF(AA14=1,0,IF(Y14=1,0,X14))) -> 0 | AD14: =IF(AB14=0,0,IF(AB13=AB14,AD13,T14)) -> 0 | AE14: =AB14-AB13 -> 0 | AF14: =-AD14*AB14 -> 0 | AG14: =AF14-AF13 -> 0 | AH14: =MAX(AE14,0)*(Inputs!$B$17+Inputs!$B$18+Inputs!$B$19)+MAX(-AE14,0)*(O14+Inputs!$B$18+Inputs!$B$19)+IF(AND(K14=1,AB14<>0),(Inputs!$B$17+Inputs!$B$18+Inputs!$B$19)+(O14+Inputs!$B$18+Inputs!$B$19),0)+MAX(AG14,0)*(Inputs!$B$20+Inputs!$B$22+Inputs!$B$23)+MAX(-AG14,0)*(Inputs!$B$21+Inputs!$B$22+Inputs!$B$23) -> 0 | AI14: =AB13*(M14-AD13*J14)+AB13*AD13*N14/Inputs!$B$16-AH14 -> 0 | AJ14: =MAX(AE14,0)*(Inputs!$B$17+Inputs!$B$24+Inputs!$B$25)+MAX(-AE14,0)*(O14+Inputs!$B$24+Inputs!$B$25)+IF(AND(K14=1,AB14<>0),(Inputs!$B$17+Inputs!$B$24+Inputs!$B$25)+(O14+Inputs!$B$24+Inputs!$B$25),0)+MAX(AG14,0)*(Inputs!$B$20+Inputs!$B$26+Inputs!$B$27)+MAX(-AG14,0)*(Inputs!$B$21+Inputs!$B$26+Inputs!$B$27) -> 0 | AK14: =AB13*(M14-AD13*J14)+AB13*AD13*(N14+Inputs!$B$14)/Inputs!$B$16-AJ14 -> 0 | AL14: =IF(AP13<>0,AQ13+1,0) -> 0 | AM14: =IF(W14="",0,IF(AND(AP13<>0,OR(ABS(W14)>Inputs!$B$7,AL14>=Inputs!$B$8,ABS(W14)<Inputs!$B$6)),1,0)) -> 0 | AN14: =IF(AM14=1,0,AP13) -> 0 | AO14: =IF(W14="",0,IF(AND(AN14=0,ABS(W14)>Inputs!$B$5,ABS(W14)<=Inputs!$B$7,W14>0),1,0)) -> 0 | AP14: =IF(W14="",0,IF(AO14=1,-SIGN(W14),AN14)) -> 0 | AQ14: =IF(W14="",0,IF(AO14=1,0,IF(AM14=1,0,AL14))) -> 0 | AR14: =IF(AP14=0,0,IF(AP13=AP14,AR13,T14)) -> 0 | AS14: =AP14-AP13 -> 0 | AT14: =-AR14*AP14 -> 0 | AU14: =AT14-AT13 -> 0 | AV14: =MAX(AS14,0)*(Inputs!$B$17+Inputs!$B$18+Inputs!$B$19)+MAX(-AS14,0)*(O14+Inputs!$B$18+Inputs!$B$19)+IF(AND(K14=1,AP14<>0),(Inputs!$B$17+Inputs!$B$18+Inputs!$B$19)+(O14+Inputs!$B$18+Inputs!$B$19),0)+MAX(AU14,0)*(Inputs!$B$20+Inputs!$B$22+Inputs!$B$23)+MAX(-AU14,0)*(Inputs!$B$21+Inputs!$B$22+Inputs!$B$23) -> 0 | AW14: =AP13*(M14-AR13*J14)+AP13*AR13*N14/Inputs!$B$16-AV14 -> 0 | AX14: =AW14-IF(AP13<>0,0.75*AR13*(Inputs!$B$13-N14)/Inputs!$B$16,0) -> 0 | AY14: =MAX(AS14,0)*(Inputs!$B$17+Inputs!$B$18+Inputs!$B$19)+MAX(-AS14,0)*(O14+Inputs!$B$18+Inputs!$B$19)+IF(AND(K14=1,AP14<>0),(Inputs!$B$17+Inputs!$B$18+Inputs!$B$19)+(O14+Inputs!$B$18+Inputs!$B$19),0) -> 0 | AZ14: =AP13*M14-AY14 -> 0 | BA14: =BA13+AI14 -> 0 | BB14: =MAX(BB13,BA14) -> 0 | BC14: =BA14-BB14 -> 0 | BD14: =A15-A14 -> 1
A15: 45062 | B15: 18326.1 | C15: 200.5 | D15: =LN(B15) -> 9.8160816 | E15: =LN(C15) -> 5.3008142 | F15: 10 | G15: 9 | H15: =D15-E15 -> 4.5152673 | I15: =D15-D14 -> -0.0044590795 | J15: =E15-E14 -> -0.0043794237 | K15: 0 | L15: 0 | M15: =IF(L15=1,J15-Carry!$B$9/Inputs!$B$16,I15) -> -0.0044590795 | N15: 0.065 | O15: 0.000125 | P15: =D15-('2 Hedge ratio'!$B$6+'2 Hedge ratio'!$B$5*E15) -> -0.0019563064 | Q15: =D15-('5 Re-specification'!$B$7+'5 Re-specification'!$B$5*E15+'5 Re-specification'!$B$6*F15) -> 0.00057969541 | R15: =MIN(F15,Inputs!$B$9) -> 10 | S15: =IF(AND(F15>=1,R15>=Inputs!$B$10),INDEX(LINEST(OFFSET(D15,-R15,0,R15,1),OFFSET(E15,-R15,0,R15,2)),1,1),"") | T15: =IF(AND(F15>=1,R15>=Inputs!$B$10),INDEX(LINEST(OFFSET(D15,-R15,0,R15,1),OFFSET(E15,-R15,0,R15,2)),1,2),"") | U15: =IF(AND(F15>=1,R15>=Inputs!$B$10),INDEX(LINEST(OFFSET(D15,-R15,0,R15,1),OFFSET(E15,-R15,0,R15,2)),1,3),"") | V15: =IF(AND(F15>=1,R15>=Inputs!$B$10),SQRT(SUMPRODUCT((OFFSET(D15,-R15,0,R15,1)-U15-T15*OFFSET(E15,-R15,0,R15,1)-S15*OFFSET(F15,-R15,0,R15,1))^2)/(R15-3)),"") | W15: =IF(AND(F15>=1,R15>=Inputs!$B$10),(D15-U15-T15*E15-S15*F15)/V15,"") | X15: =IF(AB14<>0,AC14+1,0) -> 0 | Y15: =IF(W15="",0,IF(AND(AB14<>0,OR(ABS(W15)>Inputs!$B$7,X15>=Inputs!$B$8,ABS(W15)<Inputs!$B$6)),1,0)) -> 0 | Z15: =IF(Y15=1,0,AB14) -> 0 | AA15: =IF(W15="",0,IF(AND(Z15=0,ABS(W15)>Inputs!$B$5,ABS(W15)<=Inputs!$B$7),1,0)) -> 0 | AB15: =IF(W15="",0,IF(AA15=1,-SIGN(W15),Z15)) -> 0 | AC15: =IF(W15="",0,IF(AA15=1,0,IF(Y15=1,0,X15))) -> 0 | AD15: =IF(AB15=0,0,IF(AB14=AB15,AD14,T15)) -> 0 | AE15: =AB15-AB14 -> 0 | AF15: =-AD15*AB15 -> 0 | AG15: =AF15-AF14 -> 0 | AH15: =MAX(AE15,0)*(Inputs!$B$17+Inputs!$B$18+Inputs!$B$19)+MAX(-AE15,0)*(O15+Inputs!$B$18+Inputs!$B$19)+IF(AND(K15=1,AB15<>0),(Inputs!$B$17+Inputs!$B$18+Inputs!$B$19)+(O15+Inputs!$B$18+Inputs!$B$19),0)+MAX(AG15,0)*(Inputs!$B$20+Inputs!$B$22+Inputs!$B$23)+MAX(-AG15,0)*(Inputs!$B$21+Inputs!$B$22+Inputs!$B$23) -> 0 | AI15: =AB14*(M15-AD14*J15)+AB14*AD14*N15/Inputs!$B$16-AH15 -> 0 | AJ15: =MAX(AE15,0)*(Inputs!$B$17+Inputs!$B$24+Inputs!$B$25)+MAX(-AE15,0)*(O15+Inputs!$B$24+Inputs!$B$25)+IF(AND(K15=1,AB15<>0),(Inputs!$B$17+Inputs!$B$24+Inputs!$B$25)+(O15+Inputs!$B$24+Inputs!$B$25),0)+MAX(AG15,0)*(Inputs!$B$20+Inputs!$B$26+Inputs!$B$27)+MAX(-AG15,0)*(Inputs!$B$21+Inputs!$B$26+Inputs!$B$27) -> 0 | AK15: =AB14*(M15-AD14*J15)+AB14*AD14*(N15+Inputs!$B$14)/Inputs!$B$16-AJ15 -> 0 | AL15: =IF(AP14<>0,AQ14+1,0) -> 0 | AM15: =IF(W15="",0,IF(AND(AP14<>0,OR(ABS(W15)>Inputs!$B$7,AL15>=Inputs!$B$8,ABS(W15)<Inputs!$B$6)),1,0)) -> 0 | AN15: =IF(AM15=1,0,AP14) -> 0 | AO15: =IF(W15="",0,IF(AND(AN15=0,ABS(W15)>Inputs!$B$5,ABS(W15)<=Inputs!$B$7,W15>0),1,0)) -> 0 | AP15: =IF(W15="",0,IF(AO15=1,-SIGN(W15),AN15)) -> 0 | AQ15: =IF(W15="",0,IF(AO15=1,0,IF(AM15=1,0,AL15))) -> 0 | AR15: =IF(AP15=0,0,IF(AP14=AP15,AR14,T15)) -> 0 | AS15: =AP15-AP14 -> 0 | AT15: =-AR15*AP15 -> 0 | AU15: =AT15-AT14 -> 0 | AV15: =MAX(AS15,0)*(Inputs!$B$17+Inputs!$B$18+Inputs!$B$19)+MAX(-AS15,0)*(O15+Inputs!$B$18+Inputs!$B$19)+IF(AND(K15=1,AP15<>0),(Inputs!$B$17+Inputs!$B$18+Inputs!$B$19)+(O15+Inputs!$B$18+Inputs!$B$19),0)+MAX(AU15,0)*(Inputs!$B$20+Inputs!$B$22+Inputs!$B$23)+MAX(-AU15,0)*(Inputs!$B$21+Inputs!$B$22+Inputs!$B$23) -> 0 | AW15: =AP14*(M15-AR14*J15)+AP14*AR14*N15/Inputs!$B$16-AV15 -> 0 | AX15: =AW15-IF(AP14<>0,0.75*AR14*(Inputs!$B$13-N15)/Inputs!$B$16,0) -> 0 | AY15: =MAX(AS15,0)*(Inputs!$B$17+Inputs!$B$18+Inputs!$B$19)+MAX(-AS15,0)*(O15+Inputs!$B$18+Inputs!$B$19)+IF(AND(K15=1,AP15<>0),(Inputs!$B$17+Inputs!$B$18+Inputs!$B$19)+(O15+Inputs!$B$18+Inputs!$B$19),0) -> 0 | AZ15: =AP14*M15-AY15 -> 0 | BA15: =BA14+AI15 -> 0 | BB15: =MAX(BB14,BA15) -> 0 | BC15: =BA15-BB15 -> 0 | BD15: =A16-A15 -> 1
A16: 45063 | B16: 18231.95 | C16: 199.9 | D16: =LN(B16) -> 9.8109308 | E16: =LN(C16) -> 5.2978172 | F16: 11 | G16: 8 | H16: =D16-E16 -> 4.5131136 | I16: =D16-D15 -> -0.0051507237 | J16: =E16-E15 -> -0.0029970052 | K16: 0 | L16: 0 | M16: =IF(L16=1,J16-Carry!$B$9/Inputs!$B$16,I16) -> -0.0051507237 | N16: 0.065 | O16: 0.000125 | P16: =D16-('2 Hedge ratio'!$B$6+'2 Hedge ratio'!$B$5*E16) -> -0.0043613934 | Q16: =D16-('5 Re-specification'!$B$7+'5 Re-specification'!$B$5*E16+'5 Re-specification'!$B$6*F16) -> -0.0015381762 | R16: =MIN(F16,Inputs!$B$9) -> 11 | S16: =IF(AND(F16>=1,R16>=Inputs!$B$10),INDEX(LINEST(OFFSET(D16,-R16,0,R16,1),OFFSET(E16,-R16,0,R16,2)),1,1),"") | T16: =IF(AND(F16>=1,R16>=Inputs!$B$10),INDEX(LINEST(OFFSET(D16,-R16,0,R16,1),OFFSET(E16,-R16,0,R16,2)),1,2),"") | U16: =IF(AND(F16>=1,R16>=Inputs!$B$10),INDEX(LINEST(OFFSET(D16,-R16,0,R16,1),OFFSET(E16,-R16,0,R16,2)),1,3),"") | V16: =IF(AND(F16>=1,R16>=Inputs!$B$10),SQRT(SUMPRODUCT((OFFSET(D16,-R16,0,R16,1)-U16-T16*OFFSET(E16,-R16,0,R16,1)-S16*OFFSET(F16,-R16,0,R16,1))^2)/(R16-3)),"") | W16: =IF(AND(F16>=1,R16>=Inputs!$B$10),(D16-U16-T16*E16-S16*F16)/V16,"") | X16: =IF(AB15<>0,AC15+1,0) -> 0 | Y16: =IF(W16="",0,IF(AND(AB15<>0,OR(ABS(W16)>Inputs!$B$7,X16>=Inputs!$B$8,ABS(W16)<Inputs!$B$6)),1,0)) -> 0 | Z16: =IF(Y16=1,0,AB15) -> 0 | AA16: =IF(W16="",0,IF(AND(Z16=0,ABS(W16)>Inputs!$B$5,ABS(W16)<=Inputs!$B$7),1,0)) -> 0 | AB16: =IF(W16="",0,IF(AA16=1,-SIGN(W16),Z16)) -> 0 | AC16: =IF(W16="",0,IF(AA16=1,0,IF(Y16=1,0,X16))) -> 0 | AD16: =IF(AB16=0,0,IF(AB15=AB16,AD15,T16)) -> 0 | AE16: =AB16-AB15 -> 0 | AF16: =-AD16*AB16 -> 0 | AG16: =AF16-AF15 -> 0 | AH16: =MAX(AE16,0)*(Inputs!$B$17+Inputs!$B$18+Inputs!$B$19)+MAX(-AE16,0)*(O16+Inputs!$B$18+Inputs!$B$19)+IF(AND(K16=1,AB16<>0),(Inputs!$B$17+Inputs!$B$18+Inputs!$B$19)+(O16+Inputs!$B$18+Inputs!$B$19),0)+MAX(AG16,0)*(Inputs!$B$20+Inputs!$B$22+Inputs!$B$23)+MAX(-AG16,0)*(Inputs!$B$21+Inputs!$B$22+Inputs!$B$23) -> 0 | AI16: =AB15*(M16-AD15*J16)+AB15*AD15*N16/Inputs!$B$16-AH16 -> 0 | AJ16: =MAX(AE16,0)*(Inputs!$B$17+Inputs!$B$24+Inputs!$B$25)+MAX(-AE16,0)*(O16+Inputs!$B$24+Inputs!$B$25)+IF(AND(K16=1,AB16<>0),(Inputs!$B$17+Inputs!$B$24+Inputs!$B$25)+(O16+Inputs!$B$24+Inputs!$B$25),0)+MAX(AG16,0)*(Inputs!$B$20+Inputs!$B$26+Inputs!$B$27)+MAX(-AG16,0)*(Inputs!$B$21+Inputs!$B$26+Inputs!$B$27) -> 0 | AK16: =AB15*(M16-AD15*J16)+AB15*AD15*(N16+Inputs!$B$14)/Inputs!$B$16-AJ16 -> 0 | AL16: =IF(AP15<>0,AQ15+1,0) -> 0 | AM16: =IF(W16="",0,IF(AND(AP15<>0,OR(ABS(W16)>Inputs!$B$7,AL16>=Inputs!$B$8,ABS(W16)<Inputs!$B$6)),1,0)) -> 0 | AN16: =IF(AM16=1,0,AP15) -> 0 | AO16: =IF(W16="",0,IF(AND(AN16=0,ABS(W16)>Inputs!$B$5,ABS(W16)<=Inputs!$B$7,W16>0),1,0)) -> 0 | AP16: =IF(W16="",0,IF(AO16=1,-SIGN(W16),AN16)) -> 0 | AQ16: =IF(W16="",0,IF(AO16=1,0,IF(AM16=1,0,AL16))) -> 0 | AR16: =IF(AP16=0,0,IF(AP15=AP16,AR15,T16)) -> 0 | AS16: =AP16-AP15 -> 0 | AT16: =-AR16*AP16 -> 0 | AU16: =AT16-AT15 -> 0 | AV16: =MAX(AS16,0)*(Inputs!$B$17+Inputs!$B$18+Inputs!$B$19)+MAX(-AS16,0)*(O16+Inputs!$B$18+Inputs!$B$19)+IF(AND(K16=1,AP16<>0),(Inputs!$B$17+Inputs!$B$18+Inputs!$B$19)+(O16+Inputs!$B$18+Inputs!$B$19),0)+MAX(AU16,0)*(Inputs!$B$20+Inputs!$B$22+Inputs!$B$23)+MAX(-AU16,0)*(Inputs!$B$21+Inputs!$B$22+Inputs!$B$23) -> 0 | AW16: =AP15*(M16-AR15*J16)+AP15*AR15*N16/Inputs!$B$16-AV16 -> 0 | AX16: =AW16-IF(AP15<>0,0.75*AR15*(Inputs!$B$13-N16)/Inputs!$B$16,0) -> 0 | AY16: =MAX(AS16,0)*(Inputs!$B$17+Inputs!$B$18+Inputs!$B$19)+MAX(-AS16,0)*(O16+Inputs!$B$18+Inputs!$B$19)+IF(AND(K16=1,AP16<>0),(Inputs!$B$17+Inputs!$B$18+Inputs!$B$19)+(O16+Inputs!$B$18+Inputs!$B$19),0) -> 0 | AZ16: =AP15*M16-AY16 -> 0 | BA16: =BA15+AI16 -> 0 | BB16: =MAX(BB15,BA16) -> 0 | BC16: =BA16-BB16 -> 0 | BD16: =A17-A16 -> 1
A17: 45064 | B17: 18180 | C17: 199.19 | D17: =LN(B17) -> 9.8080774 | E17: =LN(C17) -> 5.2942591 | F17: 12 | G17: 7 | H17: =D17-E17 -> 4.5138182 | I17: =D17-D16 -> -0.0028534608 | J17: =E17-E16 -> -0.0035580984 | K17: 0 | L17: 0 | M17: =IF(L17=1,J17-Carry!$B$9/Inputs!$B$16,I17) -> -0.0028534608 | N17: 0.065 | O17: 0.000125 | P17: =D17-('2 Hedge ratio'!$B$6+'2 Hedge ratio'!$B$5*E17) -> -0.003955185 | Q17: =D17-('5 Re-specification'!$B$7+'5 Re-specification'!$B$5*E17+'5 Re-specification'!$B$6*F17) -> -0.00079939204 | R17: =MIN(F17,Inputs!$B$9) -> 12 | S17: =IF(AND(F17>=1,R17>=Inputs!$B$10),INDEX(LINEST(OFFSET(D17,-R17,0,R17,1),OFFSET(E17,-R17,0,R17,2)),1,1),"") | T17: =IF(AND(F17>=1,R17>=Inputs!$B$10),INDEX(LINEST(OFFSET(D17,-R17,0,R17,1),OFFSET(E17,-R17,0,R17,2)),1,2),"") | U17: =IF(AND(F17>=1,R17>=Inputs!$B$10),INDEX(LINEST(OFFSET(D17,-R17,0,R17,1),OFFSET(E17,-R17,0,R17,2)),1,3),"") | V17: =IF(AND(F17>=1,R17>=Inputs!$B$10),SQRT(SUMPRODUCT((OFFSET(D17,-R17,0,R17,1)-U17-T17*OFFSET(E17,-R17,0,R17,1)-S17*OFFSET(F17,-R17,0,R17,1))^2)/(R17-3)),"") | W17: =IF(AND(F17>=1,R17>=Inputs!$B$10),(D17-U17-T17*E17-S17*F17)/V17,"") | X17: =IF(AB16<>0,AC16+1,0) -> 0 | Y17: =IF(W17="",0,IF(AND(AB16<>0,OR(ABS(W17)>Inputs!$B$7,X17>=Inputs!$B$8,ABS(W17)<Inputs!$B$6)),1,0)) -> 0 | Z17: =IF(Y17=1,0,AB16) -> 0 | AA17: =IF(W17="",0,IF(AND(Z17=0,ABS(W17)>Inputs!$B$5,ABS(W17)<=Inputs!$B$7),1,0)) -> 0 | AB17: =IF(W17="",0,IF(AA17=1,-SIGN(W17),Z17)) -> 0 | AC17: =IF(W17="",0,IF(AA17=1,0,IF(Y17=1,0,X17))) -> 0 | AD17: =IF(AB17=0,0,IF(AB16=AB17,AD16,T17)) -> 0 | AE17: =AB17-AB16 -> 0 | AF17: =-AD17*AB17 -> 0 | AG17: =AF17-AF16 -> 0 | AH17: =MAX(AE17,0)*(Inputs!$B$17+Inputs!$B$18+Inputs!$B$19)+MAX(-AE17,0)*(O17+Inputs!$B$18+Inputs!$B$19)+IF(AND(K17=1,AB17<>0),(Inputs!$B$17+Inputs!$B$18+Inputs!$B$19)+(O17+Inputs!$B$18+Inputs!$B$19),0)+MAX(AG17,0)*(Inputs!$B$20+Inputs!$B$22+Inputs!$B$23)+MAX(-AG17,0)*(Inputs!$B$21+Inputs!$B$22+Inputs!$B$23) -> 0 | AI17: =AB16*(M17-AD16*J17)+AB16*AD16*N17/Inputs!$B$16-AH17 -> 0 | AJ17: =MAX(AE17,0)*(Inputs!$B$17+Inputs!$B$24+Inputs!$B$25)+MAX(-AE17,0)*(O17+Inputs!$B$24+Inputs!$B$25)+IF(AND(K17=1,AB17<>0),(Inputs!$B$17+Inputs!$B$24+Inputs!$B$25)+(O17+Inputs!$B$24+Inputs!$B$25),0)+MAX(AG17,0)*(Inputs!$B$20+Inputs!$B$26+Inputs!$B$27)+MAX(-AG17,0)*(Inputs!$B$21+Inputs!$B$26+Inputs!$B$27) -> 0 | AK17: =AB16*(M17-AD16*J17)+AB16*AD16*(N17+Inputs!$B$14)/Inputs!$B$16-AJ17 -> 0 | AL17: =IF(AP16<>0,AQ16+1,0) -> 0 | AM17: =IF(W17="",0,IF(AND(AP16<>0,OR(ABS(W17)>Inputs!$B$7,AL17>=Inputs!$B$8,ABS(W17)<Inputs!$B$6)),1,0)) -> 0 | AN17: =IF(AM17=1,0,AP16) -> 0 | AO17: =IF(W17="",0,IF(AND(AN17=0,ABS(W17)>Inputs!$B$5,ABS(W17)<=Inputs!$B$7,W17>0),1,0)) -> 0 | AP17: =IF(W17="",0,IF(AO17=1,-SIGN(W17),AN17)) -> 0 | AQ17: =IF(W17="",0,IF(AO17=1,0,IF(AM17=1,0,AL17))) -> 0 | AR17: =IF(AP17=0,0,IF(AP16=AP17,AR16,T17)) -> 0 | AS17: =AP17-AP16 -> 0 | AT17: =-AR17*AP17 -> 0 | AU17: =AT17-AT16 -> 0 | AV17: =MAX(AS17,0)*(Inputs!$B$17+Inputs!$B$18+Inputs!$B$19)+MAX(-AS17,0)*(O17+Inputs!$B$18+Inputs!$B$19)+IF(AND(K17=1,AP17<>0),(Inputs!$B$17+Inputs!$B$18+Inputs!$B$19)+(O17+Inputs!$B$18+Inputs!$B$19),0)+MAX(AU17,0)*(Inputs!$B$20+Inputs!$B$22+Inputs!$B$23)+MAX(-AU17,0)*(Inputs!$B$21+Inputs!$B$22+Inputs!$B$23) -> 0 | AW17: =AP16*(M17-AR16*J17)+AP16*AR16*N17/Inputs!$B$16-AV17 -> 0 | AX17: =AW17-IF(AP16<>0,0.75*AR16*(Inputs!$B$13-N17)/Inputs!$B$16,0) -> 0 | AY17: =MAX(AS17,0)*(Inputs!$B$17+Inputs!$B$18+Inputs!$B$19)+MAX(-AS17,0)*(O17+Inputs!$B$18+Inputs!$B$19)+IF(AND(K17=1,AP17<>0),(Inputs!$B$17+Inputs!$B$18+Inputs!$B$19)+(O17+Inputs!$B$18+Inputs!$B$19),0) -> 0 | AZ17: =AP16*M17-AY17 -> 0 | BA17: =BA16+AI17 -> 0 | BB17: =MAX(BB16,BA17) -> 0 | BC17: =BA17-BB17 -> 0 | BD17: =A18-A17 -> 1
... A814: 46240 | B814: 24745 | C814: 280.5 | D814: =LN(B814) -> 10.116379 | E814: =LN(C814) -> 5.6365737 | F814: 809 | G814: 19 | H814: =D814-E814 -> 4.479805 | I814: =D814-D813 -> 0.0038465479 | J814: =E814-E813 -> 0.0017841218 | K814: 0 | L814: 0 | M814: =IF(L814=1,J814-Carry!$B$9/Inputs!$B$16,I814) -> 0.0038465479 | N814: 0.0525 | O814: 0.0005 | P814: =D814-('2 Hedge ratio'!$B$6+'2 Hedge ratio'!$B$5*E814) -> -0.0092573739 | Q814: =D814-('5 Re-specification'!$B$7+'5 Re-specification'!$B$5*E814+'5 Re-specification'!$B$6*F814) -> 0.0020334366 | R814: =MIN(F814,Inputs!$B$9) -> 250 | S814: =IF(AND(F814>=1,R814>=Inputs!$B$10),INDEX(LINEST(OFFSET(D814,-R814,0,R814,1),OFFSET(E814,-R814,0,R814,2)),1,1),"") -> -3.4288913e-05 | T814: =IF(AND(F814>=1,R814>=Inputs!$B$10),INDEX(LINEST(OFFSET(D814,-R814,0,R814,1),OFFSET(E814,-R814,0,R814,2)),1,2),"") -> 1.0180785 | U814: =IF(AND(F814>=1,R814>=Inputs!$B$10),INDEX(LINEST(OFFSET(D814,-R814,0,R814,1),OFFSET(E814,-R814,0,R814,2)),1,3),"") -> 4.4047353 | V814: =IF(AND(F814>=1,R814>=Inputs!$B$10),SQRT(SUMPRODUCT((OFFSET(D814,-R814,0,R814,1)-U814-T814*OFFSET(E814,-R814,0,R814,1)-S814*OFFSET(F814,-R814,0,R814,1))^2)/(R814-3)),"") -> 0.0023337437 | W814: =IF(AND(F814>=1,R814>=Inputs!$B$10),(D814-U814-T814*E814-S814*F814)/V814,"") -> 0.38935859 | X814: =IF(AB813<>0,AC813+1,0) -> 0 | Y814: =IF(W814="",0,IF(AND(AB813<>0,OR(ABS(W814)>Inputs!$B$7,X814>=Inputs!$B$8,ABS(W814)<Inputs!$B$6)),1,0)) -> 0 | Z814: =IF(Y814=1,0,AB813) -> 0 | AA814: =IF(W814="",0,IF(AND(Z814=0,ABS(W814)>Inputs!$B$5,ABS(W814)<=Inputs!$B$7),1,0)) -> 0 | AB814: =IF(W814="",0,IF(AA814=1,-SIGN(W814),Z814)) -> 0 | AC814: =IF(W814="",0,IF(AA814=1,0,IF(Y814=1,0,X814))) -> 0 | AD814: =IF(AB814=0,0,IF(AB813=AB814,AD813,T814)) -> 0 | AE814: =AB814-AB813 -> 0 | AF814: =-AD814*AB814 -> 0 | AG814: =AF814-AF813 -> 0 | AH814: =MAX(AE814,0)*(Inputs!$B$17+Inputs!$B$18+Inputs!$B$19)+MAX(-AE814,0)*(O814+Inputs!$B$18+Inputs!$B$19)+IF(AND(K814=1,AB814<>0),(Inputs!$B$17+Inputs!$B$18+Inputs!$B$19)+(O814+Inputs!$B$18+Inputs!$B$19),0)+MAX(AG814,0)*(Inputs!$B$20+Inputs!$B$22+Inputs!$B$23)+MAX(-AG814,0)*(Inputs!$B$21+Inputs!$B$22+Inputs!$B$23) -> 0 | AI814: =AB813*(M814-AD813*J814)+AB813*AD813*N814/Inputs!$B$16-AH814 -> 0 | AJ814: =MAX(AE814,0)*(Inputs!$B$17+Inputs!$B$24+Inputs!$B$25)+MAX(-AE814,0)*(O814+Inputs!$B$24+Inputs!$B$25)+IF(AND(K814=1,AB814<>0),(Inputs!$B$17+Inputs!$B$24+Inputs!$B$25)+(O814+Inputs!$B$24+Inputs!$B$25),0)+MAX(AG814,0)*(Inputs!$B$20+Inputs!$B$26+Inputs!$B$27)+MAX(-AG814,0)*(Inputs!$B$21+Inputs!$B$26+Inputs!$B$27) -> 0 | AK814: =AB813*(M814-AD813*J814)+AB813*AD813*(N814+Inputs!$B$14)/Inputs!$B$16-AJ814 -> 0 | AL814: =IF(AP813<>0,AQ813+1,0) -> 0 | AM814: =IF(W814="",0,IF(AND(AP813<>0,OR(ABS(W814)>Inputs!$B$7,AL814>=Inputs!$B$8,ABS(W814)<Inputs!$B$6)),1,0)) -> 0 | AN814: =IF(AM814=1,0,AP813) -> 0 | AO814: =IF(W814="",0,IF(AND(AN814=0,ABS(W814)>Inputs!$B$5,ABS(W814)<=Inputs!$B$7,W814>0),1,0)) -> 0 | AP814: =IF(W814="",0,IF(AO814=1,-SIGN(W814),AN814)) -> 0 | AQ814: =IF(W814="",0,IF(AO814=1,0,IF(AM814=1,0,AL814))) -> 0 | AR814: =IF(AP814=0,0,IF(AP813=AP814,AR813,T814)) -> 0 | AS814: =AP814-AP813 -> 0 | AT814: =-AR814*AP814 -> 0 | AU814: =AT814-AT813 -> 0 | AV814: =MAX(AS814,0)*(Inputs!$B$17+Inputs!$B$18+Inputs!$B$19)+MAX(-AS814,0)*(O814+Inputs!$B$18+Inputs!$B$19)+IF(AND(K814=1,AP814<>0),(Inputs!$B$17+Inputs!$B$18+Inputs!$B$19)+(O814+Inputs!$B$18+Inputs!$B$19),0)+MAX(AU814,0)*(Inputs!$B$20+Inputs!$B$22+Inputs!$B$23)+MAX(-AU814,0)*(Inputs!$B$21+Inputs!$B$22+Inputs!$B$23) -> 0 | AW814: =AP813*(M814-AR813*J814)+AP813*AR813*N814/Inputs!$B$16-AV814 -> 0 | AX814: =AW814-IF(AP813<>0,0.75*AR813*(Inputs!$B$13-N814)/Inputs!$B$16,0) -> 0 | AY814: =MAX(AS814,0)*(Inputs!$B$17+Inputs!$B$18+Inputs!$B$19)+MAX(-AS814,0)*(O814+Inputs!$B$18+Inputs!$B$19)+IF(AND(K814=1,AP814<>0),(Inputs!$B$17+Inputs!$B$18+Inputs!$B$19)+(O814+Inputs!$B$18+Inputs!$B$19),0) -> 0 | AZ814: =AP813*M814-AY814 -> 0 | BA814: =BA813+AI814 -> 0.016564417 | BB814: =MAX(BB813,BA814) -> 0.026172619 | BC814: =BA814-BB814 -> -0.0096082021 | BD814: =A815-A814 -> 1
